Workbook

Sheet Income Statement
A1: Alkem Laboratories Ltd | H1: Historicals | M1: Forecasted
E2: Constants | F2: Units | H2: 2022 | I2: =H2+1 -> 2023 | J2: =I2+1 -> 2024 | K2: =J2+1 -> 2025 | L2: =K2+1 -> 2026 | M2: =L2+1 -> 2027 | N2: =M2+1 -> 2028 | O2: =N2+1 -> 2029 | P2: =O2+1 -> 2030 | Q2: =P2+1 -> 2031
C3: Sales | F3: ₹ in Millions | H3: 106341.9 | I3: 115992.6 | J3: 126675.8 | K3: 129645.2 | L3: 147122.7 | M3: ='Revenue Assumptions'!M3 -> 159668.78 | N3: ='Revenue Assumptions'!N3 -> 172331.63 | O3: ='Revenue Assumptions'!O3 -> 185042.03 | P3: ='Revenue Assumptions'!P3 -> 197734.54 | Q3: ='Revenue Assumptions'!Q3 -> 210348.25
D4: Cost of Materials Consumed | F4: ₹ in Millions | H4: -32260.6 | I4: -30569.2 | J4: -32945.9 | K4: -34403.7 | L4: -35653.9 | M4: =-'Cost Assumptions'!M4 -> -38320.507 | N4: =-'Cost Assumptions'!N4 -> -41359.59 | O4: =-'Cost Assumptions'!O4 -> -44410.087 | P4: =-'Cost Assumptions'!P4 -> -47456.29 | Q4: =-'Cost Assumptions'!Q4 -> -50483.579
D5: Purchases of stock in trade | F5: ₹ in Millions | H5: -14897.1 | I5: -13875.5 | J5: -16288.7 | K5: -15140.2 | L5: -16945.5 | M5: =-'Cost Assumptions'!M5 -> -19160.254 | N5: =-'Cost Assumptions'!N5 -> -20679.795 | O5: =-'Cost Assumptions'!O5 -> -22205.043 | P5: =-'Cost Assumptions'!P5 -> -23728.145 | Q5: =-'Cost Assumptions'!Q5 -> -25241.79
D6: Changes in Inventory | F6: ₹ in Millions | H6: 5354.8 | I6: -4623.7 | J6: -141.2 | K6: 1901.3 | L6: 1671.2 | M6: =-'Cost Assumptions'!M6 -> -1437.019 | N6: =-'Cost Assumptions'!N6 -> -1550.9846 | O6: =-'Cost Assumptions'!O6 -> -1665.3783 | P6: =-'Cost Assumptions'!P6 -> -1779.6109 | Q6: =-'Cost Assumptions'!Q6 -> -1893.1342
D7: Total of Cost of Good sold | F7: ₹ in Millions | H7: =SUM(H4:H6) -> -41802.9 | I7: =SUM(I4:I6) -> -49068.4 | J7: =SUM(J4:J6) -> -49375.8 | K7: =SUM(K4:K6) -> -47642.6 | L7: =SUM(L4:L6) -> -50928.2 | M7: =SUM(M4:M6) -> -58917.78 | N7: =SUM(N4:N6) -> -63590.37 | O7: =SUM(O4:O6) -> -68280.508 | ... Q7: =SUM(Q4:Q6) -> -77618.503
C8: Gross Profit | F8: ₹ in Millions | H8: =SUM(H3,H7) -> 64539 | I8: =SUM(I3,I7) -> 66924.2 | J8: =SUM(J3,J7) -> 77300 | K8: =SUM(K3,K7) -> 82002.6 | L8: =SUM(L3,L7) -> 96194.5 | M8: =SUM(M3,M7) -> 100751 | N8: =SUM(N3,N7) -> 108741.26 | O8: =SUM(O3,O7) -> 116761.52 | ... Q8: =SUM(Q3,Q7) -> 132729.74
D9: Employee Expenses | F9: ₹ in Millions | H9: -19627.1 | I9: -21313.5 | J9: -22010.1 | K9: -24539.2 | L9: -28371.1 | M9: =-'Cost Assumptions'!M8 -> -30337.068 | N9: =-'Cost Assumptions'!N8 -> -32743.009 | O9: =-'Cost Assumptions'!O8 -> -35157.985 | P9: =-'Cost Assumptions'!P8 -> -37569.563 | Q9: =-'Cost Assumptions'!Q8 -> -39966.167
D10: Operating Expenses | F10: ₹ in Millions | H10: -24382.7 | I10: -29516.2 | J10: -32835 | K10: -32341.9 | L10: -37771.8 | M10: =-'Cost Assumptions'!M9 -> -39917.195 | N10: =-'Cost Assumptions'!N9 -> -43082.907 | O10: =-'Cost Assumptions'!O9 -> -46260.507 | P10: =-'Cost Assumptions'!P9 -> -49433.635 | Q10: =-'Cost Assumptions'!Q9 -> -52587.062
C11: EBITDA | F11: ₹ in Millions | H11: =SUM(H8:H10) -> 20529.2 | I11: =SUM(I8:I10) -> 16094.5 | J11: =SUM(J8:J10) -> 22454.9 | K11: =SUM(K8:K10) -> 25121.5 | L11: =SUM(L8:L10) -> 30051.6 | M11: =SUM(M8:M10) -> 30496.737 | N11: =SUM(N8:N10) -> 32915.341 | O11: =SUM(O8:O10) -> 35343.027 | ... Q11: =SUM(Q8:Q10) -> 40176.515
D12: Depreciation & Amortisation Expenses | F12: ₹ in Millions | H12: -3039.6 | I12: -3104.2 | J12: -2993 | K12: -3571.6 | L12: -3820.6 | M12: ='Depreciation & Amortisation'!M9 -> -4146.4067 | N12: ='Depreciation & Amortisation'!N9 -> -4475.2456 | O12: ='Depreciation & Amortisation'!O9 -> -4805.3195 | P12: ='Depreciation & Amortisation'!P9 -> -5134.9288 | Q12: ='Depreciation & Amortisation'!Q9 -> -5462.4916
C13: EBIT | F13: ₹ in Millions | H13: =SUM(H11:H12) -> 17489.6 | I13: =SUM(I11:I12) -> 12990.3 | J13: =SUM(J11:J12) -> 19461.9 | K13: =SUM(K11:K12) -> 21549.9 | L13: =SUM(L11:L12) -> 26231 | M13: =SUM(M11:M12) -> 26350.33 | N13: =SUM(N11:N12) -> 28440.095 | O13: =SUM(O11:O12) -> 30537.708 | ... Q13: =SUM(Q11:Q12) -> 34714.024
D14: Interest Expenses | F14: ₹ in Millions | H14: -523.7 | I14: -1073.6 | J14: -1124.1 | K14: -1217 | L14: -1607.8 | M14: =Debt!M8 -> -1461.15 | N14: =Debt!N8 -> -1431 | O14: =Debt!O8 -> -1333.5777 | P14: =Debt!P8 -> -1236.1554 | Q14: =Debt!Q8 -> -1159.3044
D15: Interest Income | F15: ₹ in Millions | H15: 1626.5 | I15: 2160.8 | J15: 3108.4 | K15: 4937.4 | L15: 5833.5 | M15: =L15 -> 5833.5 | N15: =M15 -> 5833.5 | O15: =N15 -> 5833.5 | P15: =O15 -> 5833.5 | Q15: =P15 -> 5833.5
D16: Profit before Tax & Exceptional Items | F16: ₹ in Millions | H16: =SUM(H13:H15) -> 18592.4 | I16: =SUM(I13:I15) -> 14077.5 | J16: =SUM(J13:J15) -> 21446.2 | K16: =SUM(K13:K15) -> 25270.3 | L16: =SUM(L13:L15) -> 30456.7 | M16: =SUM(M13:M15) -> 30722.68 | N16: =SUM(N13:N15) -> 32842.595 | O16: =SUM(O13:O15) -> 35037.63 | ... Q16: =SUM(Q13:Q15) -> 39388.219
D17: Exceptional Items | F17: ₹ in Millions | H17: -149.6 | I17: -1029.8 | J17: -1214.9 | K17: 0 | L17: -1748.3 | M17: 0 | N17: =0 -> 0 | O17: =0 -> 0 | P17: =0 -> 0 | Q17: =0 -> 0
C18: Profit before Tax | F18: ₹ in Millions | H18: =SUM(H16:H17) -> 18442.8 | I18: =SUM(I16:I17) -> 13047.7 | J18: =SUM(J16:J17) -> 20231.3 | K18: =SUM(K16:K17) -> 25270.3 | L18: =SUM(L16:L17) -> 28708.4 | M18: =SUM(M16:M17) -> 30722.68 | N18: =SUM(N16:N17) -> 32842.595 | O18: =SUM(O16:O17) -> 35037.63 | ... Q18: =SUM(Q16:Q17) -> 39388.219
D19: Current Tax | F19: ₹ in Millions | H19: -3619.8 | I19: -2739 | J19: -4222.8 | K19: -5236 | L19: -6196.6 | M19: =-M18*M31 -> -9524.0309 | N19: =-N18*N31 -> -10181.204 | O19: =-O18*O31 -> -10511.289 | P19: =-P18*P31 -> -10796.617 | Q19: =-Q18*Q31 -> -11028.701
D20: Deferred Tax | F20: ₹ in Millions | H20: 1980.2 | I20: -240.6 | J20: 2106.1 | K20: 2125.7 | L20: 1019 | M20: 0 | N20: 0 | O20: 0 | P20: 0 | Q20: 0
D21: Loss from Associates | F21: ₹ in Millions | H21: 0 | I21: 0 | J21: 0 | K21: -6.2 | L21: -19.7 | M21: 0 | N21: 0 | O21: 0 | P21: 0 | Q21: 0
C22: PAT | F22: ₹ in Millions | H22: =SUM(H18:H21) -> 16803.2 | I22: =SUM(I18:I21) -> 10068.1 | J22: =SUM(J18:J21) -> 18114.6 | K22: =SUM(K18:K21) -> 22153.8 | L22: =SUM(L18:L21) -> 23511.1 | M22: =SUM(M18:M21) -> 21198.649 | N22: =SUM(N18:N21) -> 22661.391 | O22: =SUM(O18:O21) -> 24526.341 | ... Q22: =SUM(Q18:Q21) -> 28359.518
D23: Profit to Non-Controling Interest (NCI) | F23: ₹ in Millions | H23: 347 | I23: 226.4 | J23: 156.9 | K23: 499 | L23: 493.6 | M23: =L23 -> 493.6 | N23: =M23 -> 493.6 | O23: =N23 -> 493.6 | P23: =O23 -> 493.6 | Q23: =P23 -> 493.6
D24: Profit to Share holders | F24: ₹ in Millions | H24: 16456.2 | I24: 9841.7 | J24: 17957.7 | K24: 21654.8 | L24: 23018 | M24: =M22-M23 -> 20705.049 | N24: =N22-N23 -> 22167.791 | O24: =O22-O23 -> 24032.741 | P24: =P22-P23 -> 25939.496 | Q24: =Q22-Q23 -> 27865.918
D25: Other Comprehensive Income (OCI) | F25: ₹ in Millions | H25: 341.4 | I25: 1149 | J25: 200.4 | K25: 197.2 | L25: 1837.9 | M25: =L25 -> 1837.9 | N25: =M25 -> 1837.9 | O25: =N25 -> 1837.9 | P25: =O25 -> 1837.9 | Q25: =P25 -> 1837.9
D26: PAT + OCI | F26: ₹ in Millions | H26: =SUM(H23:H25) -> 17144.6 | I26: =SUM(I23:I25) -> 11217.1 | J26: =SUM(J23:J25) -> 18315 | K26: =SUM(K23:K25) -> 22351 | L26: =SUM(L23:L25) -> 25349.5 | M26: =SUM(M23:M25) -> 23036.549 | N26: =SUM(N23:N25) -> 24499.291 | O26: =SUM(O23:O25) -> 26364.241 | ... Q26: =SUM(Q23:Q25) -> 30197.418
D27: Profit to NCI | F27: ₹ in Millions | H27: 342.9 | I27: 222.3 | J27: 150.8 | K27: 488.7 | L27: 507.7 | M27: =L27 -> 507.7 | N27: =M27 -> 507.7 | O27: =N27 -> 507.7 | P27: =O27 -> 507.7 | Q27: =P27 -> 507.7
D28: Profit to Share holders | F28: ₹ in Millions | H28: 16801.7 | I28: 10994.8 | J28: 18164.2 | K28: 21862.3 | L28: 24841.8 | M28: =M26-M27 -> 22528.849 | N28: =N26-N27 -> 23991.591 | O28: =O26-O27 -> 25856.541 | P28: =P26-P27 -> 27763.296 | Q28: =Q26-Q27 -> 29689.718
C29: Basic & Diluted EPS | F29: ₹ | H29: 137.63 | I29: 82.31 | J29: 150.19 | K29: 181.11 | L29: 192.51 | M29: =M34 -> 173.16982 | N29: =N34 -> 185.40368 | O29: =O34 -> 201.00147 | P29: =P34 -> 216.94891 | Q29: =Q34 -> 233.06083
D31: Tax Rate | F31: % | H31: =-SUM(H19:H20)/H18 -> 0.088901902 | I31: =-SUM(I19:I20)/I18 -> 0.22836209 | J31: =-SUM(J19:J20)/J18 -> 0.10462501 | K31: =-SUM(K19:K20)/K18 -> 0.12308125 | L31: =-SUM(L19:L20)/L18 -> 0.1803514 | M31: 0.31 | N31: =M31 -> 0.31 | O31: 0.3 | P31: 0.29 | Q31: 0.28
D32: Total Dividend Paid | F32: ₹ in Millions | H32: =-'Cash Flow Statement'!H42 -> 4219.1 | I32: =-'Cash Flow Statement'!I42 -> 5295.2 | J32: =-'Cash Flow Statement'!J42 -> 5404.9 | K32: =-'Cash Flow Statement'!K42 -> 5046.2 | L32: =-'Cash Flow Statement'!L42 -> 6137 | M32: =M22*M36 -> 5299.6624 | N32: =N22*N36 -> 5665.3477 | O32: =O22*O36 -> 6131.5853 | P32: =P22*P36 -> 6608.2741 | Q32: =Q22*Q36 -> 7089.8795
D33: Weighted average number of equity shares | F33: in Millions | H33: 119.565 | I33: 119.565 | J33: 119.565 | K33: 119.565 | L33: 119.565 | M33: =L33 -> 119.565 | N33: =M33 -> 119.565 | O33: =N33 -> 119.565 | P33: =O33 -> 119.565 | Q33: =P33 -> 119.565
D34: Earning Per Share (Basic & Diluted) | F34: ₹ | H34: =H29 -> 137.63 | I34: =I29 -> 82.31 | J34: =J29 -> 150.19 | K34: =K29 -> 181.11 | L34: =L29 -> 192.51 | M34: =M24/M33 -> 173.16982 | N34: =N24/N33 -> 185.40368 | O34: =O24/O33 -> 201.00147 | P34: =P24/P33 -> 216.94891 | Q34: =Q24/Q33 -> 233.06083
D35: Dividend Per Share | F35: ₹ | H35: =H32/H33 -> 35.287082 | I35: =I32/I33 -> 44.287208 | J35: =J32/J33 -> 45.2047 | K35: =K32/K33 -> 42.204659 | L35: =L32/L33 -> 51.32773 | M35: =M32/M33 -> 44.32453 | N35: =N32/N33 -> 47.382994 | O35: =O32/O33 -> 51.282443 | ... Q35: =Q32/Q33 -> 59.297282
D36: Dividend Pay Out Ratio | F36: % | H36: =H32/H22 -> 0.25108908 | I36: =I32/I22 -> 0.52593836 | J36: =J32/J22 -> 0.29837258 | K36: =K32/K22 -> 0.22778034 | L36: =L32/L22 -> 0.26102564 | M36: 0.25 | N36: 0.25 | O36: 0.25 | P36: 0.25 | Q36: 0.25
C38: Ratios
D39: Gross Profit Margin | F39: % | H39: =H8/H3 -> 0.60690095 | I39: =I8/I3 -> 0.57696957 | J39: =J8/J3 -> 0.61021916 | K39: =K8/K3 -> 0.63251551 | L39: =L8/L3 -> 0.6538386 | M39: =M8/M3 -> 0.631 | N39: =N8/N3 -> 0.631 | O39: =O8/O3 -> 0.631 | ... Q39: =Q8/Q3 -> 0.631
D40: EBITDA Margin | F40: % | H40: =H11/H3 -> 0.19304902 | I40: =I11/I3 -> 0.13875454 | J40: =J11/J3 -> 0.17726274 | K40: =K11/K3 -> 0.19377115 | L40: =L11/L3 -> 0.20426216 | M40: =M11/M3 -> 0.191 | N40: =N11/N3 -> 0.191 | O40: =O11/O3 -> 0.191 | ... Q40: =Q11/Q3 -> 0.191
D41: EBIT Margin | F41: % | H41: =H13/H3 -> 0.16446575 | I41: =I13/I3 -> 0.11199249 | J41: =J13/J3 -> 0.1536355 | K41: =K13/K3 -> 0.16622212 | L41: =L13/L3 -> 0.17829336 | M41: =M13/M3 -> 0.1650312 | N41: =N13/N3 -> 0.1650312 | O41: =O13/O3 -> 0.1650312 | ... Q41: =Q13/Q3 -> 0.1650312
D42: PAT Margin | F42: % | H42: =H22/H3 -> 0.15801109 | I42: =I22/I3 -> 0.086799503 | J42: =J22/J3 -> 0.14299969 | K42: =K22/K3 -> 0.17088022 | L42: =L22/L3 -> 0.15980607 | M42: =M22/M3 -> 0.1327664 | N42: =N22/N3 -> 0.13149873 | O42: =O22/O3 -> 0.13254471 | ... Q42: =Q22/Q3 -> 0.13482175

Sheet Balance sheet
A1: Alkem Laboratories Ltd | H1: Historicals | M1: Forecasted
E2: Constants | F2: Units | H2: 2022 | I2: =H2+1 -> 2023 | J2: =I2+1 -> 2024 | K2: =J2+1 -> 2025 | L2: =K2+1 -> 2026 | M2: =L2+1 -> 2027 | N2: =M2+1 -> 2028 | O2: =N2+1 -> 2029 | P2: =O2+1 -> 2030 | Q2: =P2+1 -> 2031
C3: Current Assets
D4: Cash and cash equivalents | F4: ₹ in Millions | H4: 2321.8 | I4: 2738 | J4: 4550.7 | K4: 3041.4 | L4: 2479.1 | M4: ='Cash Flow Statement'!M49 -> 17254.306 | N4: ='Cash Flow Statement'!N49 -> 30716.603 | O4: ='Cash Flow Statement'!O49 -> 45640.41 | P4: ='Cash Flow Statement'!P49 -> 62303.529 | Q4: ='Cash Flow Statement'!Q49 -> 80508.409
D5: Bank balances | F5: ₹ in Millions | H5: 23464 | I5: 23430.9 | J5: 11242.8 | K5: 12589.4 | L5: 14849.9 | M5: =L5 -> 14849.9 | N5: =M5 -> 14849.9 | O5: =N5 -> 14849.9 | P5: =O5 -> 14849.9 | Q5: =P5 -> 14849.9
D6: Trade receivables | F6: ₹ in Millions | H6: 18846 | I6: 21321.8 | J6: 22528.1 | K6: 24662.5 | L6: 29791.1 | M6: ='Working Capital'!M5 -> 31933.756 | N6: ='Working Capital'!N5 -> 34466.325 | O6: ='Working Capital'!O5 -> 37008.406 | P6: ='Working Capital'!P5 -> 39546.908 | Q6: ='Working Capital'!Q5 -> 42069.65
D7: Inventories | F7: ₹ in Millions | H7: 30055.3 | I7: 26075.3 | J7: 26611.8 | K7: 29224.1 | L7: 33332.2 | M7: ='Working Capital'!M6 -> 37933.365 | N7: ='Working Capital'!N6 -> 40941.745 | O7: ='Working Capital'!O6 -> 43961.423 | P7: ='Working Capital'!P6 -> 46976.851 | Q7: ='Working Capital'!Q6 -> 49973.557
D8: Investments | F8: ₹ in Millions | H8: 1393.1 | I8: 3172.1 | J8: 1489.9 | K8: 9022.6 | L8: 7373.1 | M8: =L8 -> 7373.1 | N8: =M8 -> 7373.1 | O8: =N8 -> 7373.1 | P8: =O8 -> 7373.1 | Q8: =P8 -> 7373.1
D9: Loans | F9: ₹ in Millions | H9: 202.5 | I9: 67.7 | J9: 90.7 | K9: 90.4 | L9: 66.3 | M9: 0 | N9: 0 | O9: 0 | P9: 0 | Q9: 0
D10: Other financial assets | F10: ₹ in Millions | H10: 1731.5 | I10: 1897.5 | J10: 29302 | K10: 21154.8 | L10: 25225.2 | M10: =L10 -> 25225.2 | N10: =M10 -> 25225.2 | O10: =N10 -> 25225.2 | P10: =O10 -> 25225.2 | Q10: =P10 -> 25225.2
D11: Other current assets | F11: ₹ in Millions | H11: 6322.8 | I11: 7360.9 | J11: 8299.8 | K11: 8326.7 | L11: 8988.3 | M11: =L11 -> 8988.3 | N11: =M11 -> 8988.3 | O11: =N11 -> 8988.3 | P11: =O11 -> 8988.3 | Q11: =P11 -> 8988.3
D12: Non Current Asset held for Sale | F12: ₹ in Millions | H12: 17.3 | I12: 1232.6 | J12: 0 | K12: 1346.3 | L12: 0 | M12: =0 -> 0 | N12: =0 -> 0 | O12: =0 -> 0 | P12: =0 -> 0 | Q12: =0 -> 0
C13: Total Current Assets | F13: ₹ in Millions | H13: =SUM(H4:H12) -> 84354.3 | I13: =SUM(I4:I12) -> 87296.8 | J13: =SUM(J4:J12) -> 104115.8 | K13: =SUM(K4:K12) -> 109458.2 | L13: =SUM(L4:L12) -> 122105.2 | M13: =SUM(M4:M12) -> 143557.93 | N13: =SUM(N4:N12) -> 162561.17 | O13: =SUM(O4:O12) -> 183046.74 | ... Q13: =SUM(Q4:Q12) -> 228988.12
C14: Non Current Assets | F14: ₹ in Millions
D15: Property, plant and equipment | F15: ₹ in Millions | H15: 22871 | I15: 20654 | J15: 21614.6 | K15: 20639.3 | L15: 26949.7 | M15: ='Depreciation & Amortisation'!M11 -> 24607.551 | N15: ='Depreciation & Amortisation'!N11 -> 23578.938 | O15: ='Depreciation & Amortisation'!O11 -> 22474.459 | P15: ='Depreciation & Amortisation'!P11 -> 21294.221 | Q15: ='Depreciation & Amortisation'!Q11 -> 20038.694
D16: Right of use Assets | F16: ₹ in Millions | H16: 0 | I16: 1378.5 | J16: 2471.7 | K16: 3222.2 | L16: 3956.6 | M16: =L16 -> 3956.6 | N16: =M16 -> 3956.6 | O16: =N16 -> 3956.6 | P16: =O16 -> 3956.6 | Q16: =P16 -> 3956.6
D17: Capital work in progress | F17: ₹ in Millions | H17: 3394.8 | I17: 3102.7 | J17: 1484 | K17: 4765.5 | L17: 1379.1 | M17: =L17 -> 1379.1 | N17: =M17 -> 1379.1 | O17: =N17 -> 1379.1 | P17: =O17 -> 1379.1 | Q17: =P17 -> 1379.1
D18: Goodwill | F18: ₹ in Millions | H18: 4030.9 | I18: 4131.7 | J18: 4167.4 | K18: 4231.1 | L18: 5236.4 | M18: =L18 -> 5236.4 | N18: =M18 -> 5236.4 | O18: =N18 -> 5236.4 | P18: =O18 -> 5236.4 | Q18: =P18 -> 5236.4
D19: Other intangible assets | F19: ₹ in Millions | H19: 2115.4 | I19: 664.1 | J19: 474.1 | K19: 430.5 | L19: 2567.6 | M19: =L19 -> 2567.6 | N19: =M19 -> 2567.6 | O19: =N19 -> 2567.6 | P19: =O19 -> 2567.6 | Q19: =P19 -> 2567.6
D20: Intangible Assets under Development | F20: ₹ in Millions | H20: 0 | I20: 129.7 | J20: 101.7 | K20: 715.2 | L20: 1438.8 | M20: =L20 -> 1438.8 | N20: =M20 -> 1438.8 | O20: =N20 -> 1438.8 | P20: =O20 -> 1438.8 | Q20: =P20 -> 1438.8
D21: Investments in Associates | F21: ₹ in Millions | H21: 2316.7 | I21: 3046.1 | J21: 3348 | K21: 9108.6 | L21: 10966.9 | M21: =L21 -> 10966.9 | N21: =M21 -> 10966.9 | O21: =N21 -> 10966.9 | P21: =O21 -> 10966.9 | Q21: =P21 -> 10966.9
D22: Loans | F22: ₹ in Millions | H22: 80.2 | I22: 80.2 | J22: 0 | K22: 323.8 | L22: 348.1 | M22: =L22 -> 348.1 | N22: =M22 -> 348.1 | O22: =N22 -> 348.1 | P22: =O22 -> 348.1 | Q22: =P22 -> 348.1
D23: Other financial assets | F23: ₹ in Millions | H23: 7106.7 | I23: 2952.5 | J23: 1202.2 | K23: 4753.6 | L23: 12157.4 | M23: =L23 -> 12157.4 | N23: =M23 -> 12157.4 | O23: =N23 -> 12157.4 | P23: =O23 -> 12157.4 | Q23: =P23 -> 12157.4
D24: Deferred tax assets (net) | F24: ₹ in Millions | H24: 13092.6 | I24: 13025 | J24: 15148.3 | K24: 17382.5 | L24: 18193.5 | M24: =L24 -> 18193.5 | N24: =M24 -> 18193.5 | O24: =N24 -> 18193.5 | P24: =O24 -> 18193.5 | Q24: =P24 -> 18193.5
D25: Non-current tax assets (net) | F25: ₹ in Millions | H25: 533.1 | I25: 575.4 | J25: 781.7 | K25: 647.1 | L25: 799.6 | M25: =L25 -> 799.6 | N25: =M25 -> 799.6 | O25: =N25 -> 799.6 | P25: =O25 -> 799.6 | Q25: =P25 -> 799.6
D26: Other non-current assets | F26: ₹ in Millions | H26: 796.2 | I26: 529.8 | J26: 839.5 | K26: 1233.4 | L26: 2630.8 | M26: =L26 -> 2630.8 | N26: =M26 -> 2630.8 | O26: =N26 -> 2630.8 | P26: =O26 -> 2630.8 | Q26: =P26 -> 2630.8
C27: Total Non Current Assets | F27: ₹ in Millions | H27: =SUM(H15:H26) -> 56337.6 | I27: =SUM(I15:I26) -> 50269.7 | J27: =SUM(J15:J26) -> 51633.2 | K27: =SUM(K15:K26) -> 67452.8 | L27: =SUM(L15:L26) -> 86624.5 | M27: =SUM(M15:M26) -> 84282.351 | N27: =SUM(N15:N26) -> 83253.738 | O27: =SUM(O15:O26) -> 82149.259 | ... Q27: =SUM(Q15:Q26) -> 79713.494
A28: x | C28: Total Assets | F28: ₹ in Millions | H28: =SUM(H13,H27) -> 140691.9 | I28: =SUM(I13,I27) -> 137566.5 | J28: =SUM(J13,J27) -> 155749 | K28: =SUM(K13,K27) -> 176911 | L28: =SUM(L13,L27) -> 208729.7 | M28: =SUM(M13,M27) -> 227840.28 | N28: =SUM(N13,N27) -> 245814.91 | O28: =SUM(O13,O27) -> 265196 | ... Q28: =SUM(Q13,Q27) -> 308701.61
C29: Current Liabilities | F29: ₹ in Millions
D30: Trade payables | F30: ₹ in Millions | H30: 11733.8 | I30: 11650.3 | J30: 17481.2 | K30: 18393.5 | L30: 22441.8 | M30: ='Working Capital'!M7 -> 25988.391 | N30: ='Working Capital'!N7 -> 28049.451 | O30: ='Working Capital'!O7 -> 30118.252 | P30: ='Working Capital'!P7 -> 32184.141 | Q30: ='Working Capital'!Q7 -> 34237.203
D31: Borrowings | F31: ₹ in Millions | H31: 25707.4 | I31: 13071.5 | J31: 11739.7 | K31: 7518.8 | L31: 11310.5 | M31: =Debt!M13 -> 11187.5 | N31: =Debt!N13 -> 11934.97 | O31: =Debt!O13 -> 11934.97 | P31: =Debt!P13 -> 11706.4 | Q31: =Debt!Q13 -> 11706.4
D32: Lease liabilities | F32: ₹ in Millions | H32: 216 | I32: 192 | J32: 151.8 | K32: 506.9 | L32: 468.8 | M32: =L32 -> 468.8 | N32: =M32 -> 468.8 | O32: =N32 -> 468.8 | P32: =O32 -> 468.8 | Q32: =P32 -> 468.8
D33: Other financial liabilities | F33: ₹ in Millions | H33: 5993.8 | I33: 6326.9 | J33: 6457.7 | K33: 7908.6 | L33: 7742.3 | M33: =L33 -> 7742.3 | N33: =M33 -> 7742.3 | O33: =N33 -> 7742.3 | P33: =O33 -> 7742.3 | Q33: =P33 -> 7742.3
D34: Other current liabilities | F34: ₹ in Millions | H34: 1503.2 | I34: 1868.9 | J34: 2296.5 | K34: 3057 | L34: 3191.7 | M34: =L34 -> 3191.7 | N34: =M34 -> 3191.7 | O34: =N34 -> 3191.7 | P34: =O34 -> 3191.7 | Q34: =P34 -> 3191.7
D35: Provisions | F35: ₹ in Millions | H35: 2736 | I35: 3727.5 | J35: 1268.7 | K35: 1591.1 | L35: 2006.5 | M35: =L35 -> 2006.5 | N35: =M35 -> 2006.5 | O35: =N35 -> 2006.5 | P35: =O35 -> 2006.5 | Q35: =P35 -> 2006.5
D36: Current tax liabilities (net) | F36: ₹ in Millions | H36: 163.2 | I36: 234.4 | J36: 549.9 | K36: 611 | L36: 665.4 | M36: =L36 -> 665.4 | N36: =M36 -> 665.4 | O36: =N36 -> 665.4 | P36: =O36 -> 665.4 | Q36: =P36 -> 665.4
D37: Liabiliteis held for sale | F37: ₹ in Millions | H37: 0 | I37: 0 | J37: 0 | K37: 62.9 | L37: 0 | M37: =0 -> 0 | N37: =0 -> 0 | O37: =0 -> 0 | P37: =0 -> 0 | Q37: =0 -> 0
C38: Toal Current Liabilities | F38: ₹ in Millions | H38: =SUM(H30:H37) -> 48053.4 | I38: =SUM(I30:I37) -> 37071.5 | J38: =SUM(J30:J37) -> 39945.5 | K38: =SUM(K30:K37) -> 39649.8 | L38: =SUM(L30:L37) -> 47827 | M38: =SUM(M30:M37) -> 51250.591 | N38: =SUM(N30:N37) -> 54059.121 | O38: =SUM(O30:O37) -> 56127.922 | ... Q38: =SUM(Q30:Q37) -> 60018.303
C39: Non Current Liabilities | F39: ₹ in Millions
D40: Borrowings | F40: ₹ in Millions | H40: 93.8 | I40: 0 | J40: 400 | K40: 3109.1 | L40: 4924.5 | M40: =Debt!M14 -> 4712.5 | N40: =Debt!N14 -> 2882.56 | O40: =Debt!O14 -> 1800.09 | P40: =Debt!P14 -> 1174.76 | Q40: =Debt!Q14 -> 320.86
...

Sheet Cash Flow Statement
A1: Alkem Laboratories Ltd | H1: Historicals | M1: Forecasted
E2: Constants | F2: Units | H2: 2022 | I2: =H2+1 -> 2023 | J2: =I2+1 -> 2024 | K2: =J2+1 -> 2025 | L2: =K2+1 -> 2026 | M2: =L2+1 -> 2027 | N2: =M2+1 -> 2028 | O2: =N2+1 -> 2029 | P2: =O2+1 -> 2030 | Q2: =P2+1 -> 2031
C3: Cash flow from Operations
D4: Profit before Tax | F4: ₹ in Millions | H4: 18442.8 | I4: 13047.7 | J4: 20231.3 | K4: 25270.3 | L4: 28708.9 | M4: ='Income Statement'!M18 -> 30722.68 | N4: ='Income Statement'!N18 -> 32842.595 | O4: ='Income Statement'!O18 -> 35037.63 | P4: ='Income Statement'!P18 -> 37229.713 | Q4: ='Income Statement'!Q18 -> 39388.219
C5: Adjustments;
D6: Depreciation and amortisation expense | F6: ₹ in Millions | H6: 3039.6 | I6: 3104.2 | J6: 2993 | K6: 3571.6 | L6: 3820.6 | M6: =-'Income Statement'!M12 -> 4146.4067 | N6: =-'Income Statement'!N12 -> 4475.2456 | O6: =-'Income Statement'!O12 -> 4805.3195 | P6: =-'Income Statement'!P12 -> 5134.9288 | Q6: =-'Income Statement'!Q12 -> 5462.4916
D7: Liabilities no longer required written back | F7: ₹ in Millions | H7: -160.1 | I7: -17.5 | J7: -19.8 | K7: -155.1 | L7: -244.8 | M7: 0 | N7: 0 | O7: 0 | P7: 0 | Q7: 0
D8: Profit on sale of investments | F8: ₹ in Millions | H8: -33.8 | I8: -21.6 | J8: -146.3 | K8: -110.2 | L8: -646.9 | M8: 0 | N8: 0 | O8: 0 | P8: 0 | Q8: 0
D9: Unrealised (gain) / loss on fair valuation of investments | F9: ₹ in Millions | H9: 69 | I9: -287 | J9: -5.4 | K9: -418.7 | L9: 109.1 | M9: 0 | N9: 0 | O9: 0 | P9: 0 | Q9: 0
D10: Profit on sale of property plant and equipment (net) | F10: ₹ in Millions | H10: 14.3 | I10: 123.6 | J10: 31.8 | K10: -46 | L10: -127.8 | M10: 0 | N10: 0 | O10: 0 | P10: 0 | Q10: 0
D11: Employee Stock Compensation Expenses | F11: ₹ in Millions | H11: 0 | I11: 0 | J11: 189.4 | K11: 166.1 | L11: 48.7 | M11: 0 | N11: 0 | O11: 0 | P11: 0 | Q11: 0
D12: Unrealised foreign currency (gain) / loss on revaluation (net) | F12: ₹ in Millions | H12: -177 | I12: -118.8 | J12: 594.3 | K12: 111.6 | L12: -160.3 | M12: 0 | N12: 0 | O12: 0 | P12: 0 | Q12: 0
D13: Dividend Income | F13: ₹ in Millions | H13: -1.9 | I13: -1.9 | J13: -1.9 | K13: -1.7 | L13: -0.8 | M13: 0 | N13: 0 | O13: 0 | P13: 0 | Q13: 0
D14: Impairment loss on property, plant and equipment | F14: ₹ in Millions | H14: 11.2 | I14: 1051.5 | J14: 992.2 | K14: 137.3 | L14: 0 | M14: 0 | N14: 0 | O14: 0 | P14: 0 | Q14: 0
D15: Interest Income | F15: ₹ in Millions | H15: -1226.8 | I15: -1711.4 | J15: -2757.7 | K15: -3587.8 | L15: -3916.4 | M15: 0 | N15: 0 | O15: 0 | P15: 0 | Q15: 0
D16: Interest expenses | F16: ₹ in Millions | H16: 523.7 | I16: 1073.6 | J16: 1124.1 | K16: 1217 | L16: 1607.8 | M16: =-'Income Statement'!M14 -> 1461.15 | N16: =-'Income Statement'!N14 -> 1431 | O16: =-'Income Statement'!O14 -> 1333.5777 | P16: =-'Income Statement'!P14 -> 1236.1554 | Q16: =-'Income Statement'!Q14 -> 1159.3044
D17: Loss Allowance | F17: ₹ in Millions | H17: 0 | I17: 0 | J17: 524 | K17: 133.7 | L17: 737.7 | M17: 0 | N17: 0 | O17: 0 | P17: 0 | Q17: 0
D18: Allowances for doubtful debts | F18: ₹ in Millions | H18: 27.8 | I18: 48.8 | J18: 318 | K18: 20.2 | L18: 136.4 | M18: 0 | N18: 0 | O18: 0 | P18: 0 | Q18: 0
C19: Operating profit before working Capital Changes | F19: ₹ in Millions | H19: =SUM(H4:H18) -> 20528.8 | I19: =SUM(I4:I18) -> 16291.2 | J19: =SUM(J4:J18) -> 24067 | K19: =SUM(K4:K18) -> 26308.3 | L19: =SUM(L4:L18) -> 30072.2 | M19: =SUM(M4:M18) -> 36330.237 | N19: =SUM(N4:N18) -> 38748.841 | O19: =SUM(O4:O18) -> 41176.527 | ... Q19: =SUM(Q4:Q18) -> 46010.015
C20: Working Capital Changes;
D21: (Increase) in trade receivables | F21: ₹ in Millions | H21: -2217.5 | I21: -1347.1 | J21: -2219.9 | K21: -2185.5 | L21: -3288.7 | M21: ='Balance sheet'!L6-'Balance sheet'!M6 -> -2142.6561 | N21: ='Balance sheet'!M6-'Balance sheet'!N6 -> -2532.5693 | O21: ='Balance sheet'!N6-'Balance sheet'!O6 -> -2542.0803 | P21: ='Balance sheet'!O6-'Balance sheet'!P6 -> -2538.5026 | Q21: ='Balance sheet'!P6-'Balance sheet'!Q6 -> -2522.7413
D22: (Increase) / Decrease in loans, other financial assets and other assets | F22: ₹ in Millions | H22: -435.8 | I22: -770.1 | J22: -1351.1 | K22: 249.9 | L22: -875.4 | M22: ='Balance sheet'!L9-'Balance sheet'!M9 -> 66.3 | N22: ='Balance sheet'!M9-'Balance sheet'!N9 -> 0 | O22: ='Balance sheet'!N9-'Balance sheet'!O9 -> 0 | P22: ='Balance sheet'!O9-'Balance sheet'!P9 -> 0 | Q22: ='Balance sheet'!P9-'Balance sheet'!Q9 -> 0
D23: (Increase) in inventories | F23: ₹ in Millions | H23: -6731.4 | I23: 4734.1 | J23: -734 | K23: -2612.3 | L23: -2473.1 | M23: ='Balance sheet'!L7-'Balance sheet'!M7 -> -4601.1652 | N23: ='Balance sheet'!M7-'Balance sheet'!N7 -> -3008.3801 | O23: ='Balance sheet'!N7-'Balance sheet'!O7 -> -3019.678 | P23: ='Balance sheet'!O7-'Balance sheet'!P7 -> -3015.4281 | Q23: ='Balance sheet'!P7-'Balance sheet'!Q7 -> -2996.7056
D24: Increase / (Decrease) in trade payable, other financial liabilities and other liabilities | F24: ₹ in Millions | H24: 3344.9 | I24: 145.1 | J24: 5252.8 | K24: 2166.5 | L24: 1214.2 | M24: ='Balance sheet'!M30-'Balance sheet'!L30 -> 3546.5906 | N24: ='Balance sheet'!N30-'Balance sheet'!M30 -> 2061.0604 | O24: ='Balance sheet'!O30-'Balance sheet'!N30 -> 2068.8007 | P24: ='Balance sheet'!P30-'Balance sheet'!O30 -> 2065.889 | Q24: ='Balance sheet'!Q30-'Balance sheet'!P30 -> 2053.0621
D25: Increase in provisions | F25: ₹ in Millions | H25: 590.2 | I25: 505.7 | J25: -1464.7 | K25: 241.7 | L25: 1271.3 | M25: 0 | N25: 0 | O25: 0 | P25: 0 | Q25: 0
D26: Income taxes paid | F26: ₹ in Millions | H26: -3969 | I26: -2733.9 | J26: -4069.4 | K26: -5040.2 | L26: -6290.2 | M26: ='Income Statement'!M19 -> -9524.0309 | N26: ='Income Statement'!N19 -> -10181.204 | O26: ='Income Statement'!O19 -> -10511.289 | P26: ='Income Statement'!P19 -> -10796.617 | Q26: ='Income Statement'!Q19 -> -11028.701
A27: x | C27: Cash Generated from operating Activities | F27: ₹ in Millions | H27: =SUM(H19:H26) -> 11110.2 | I27: =SUM(I19:I26) -> 16825 | J27: =SUM(J19:J26) -> 19480.7 | K27: =SUM(K19:K26) -> 19128.4 | L27: =SUM(L19:L26) -> 19630.3 | M27: =SUM(M19:M26) -> 23675.275 | N27: =SUM(N19:N26) -> 25087.747 | O27: =SUM(O19:O26) -> 27172.281 | ... Q27: =SUM(Q19:Q26) -> 31514.929
C28: Cash flow from Investing Activities
D29: Purchases of property, plant and equipment | F29: ₹ in Millions | H29: -3388.8 | I29: -2329.1 | J29: -2592.9 | K29: -6756.2 | L29: -6172.6 | M29: =-'Depreciation & Amortisation'!M4 -> -1804.2572 | N29: =-'Depreciation & Amortisation'!N4 -> -3446.6325 | O29: =-'Depreciation & Amortisation'!O4 -> -3700.8406 | P29: =-'Depreciation & Amortisation'!P4 -> -3954.6908 | Q29: =-'Depreciation & Amortisation'!Q4 -> -4206.965
D30: Sale of property, plant and equipment | F30: ₹ in Millions | H30: 109 | I30: 32 | J30: 724.8 | K30: 408.4 | L30: 1303.1 | M30: 0 | N30: 0 | O30: 0 | P30: 0 | Q30: 0
D31: Purchase of / Proceeds from sale of investments (net) | F31: ₹ in Millions | H31: -409.3 | I31: -2175.3 | J31: 1605.4 | K31: 2975.8 | L31: 550.6 | M31: 0 | N31: 0 | O31: 0 | P31: 0 | Q31: 0
D32: Investment made in bank deposits | F32: ₹ in Millions | H32: -11641.8 | I32: 4129.8 | J32: -12217 | K32: -12764.4 | L32: -13531.9 | M32: 0 | N32: 0 | O32: 0 | P32: 0 | Q32: 0
D33: Dividend received | F33: ₹ in Millions | H33: 1.9 | I33: 1.9 | J33: 1.9 | K33: 1.7 | L33: 0.8 | M33: 0 | N33: 0 | O33: 0 | P33: 0 | Q33: 0
D34: Interest received | F34: ₹ in Millions | H34: 977.7 | I34: 1469.1 | J34: 2392.8 | K34: 3477.1 | L34: 3276.3 | M34: 0 | N34: 0 | O34: 0 | P34: 0 | Q34: 0
D35: Investment in Associates | F35: ₹ in Millions | H35: 0 | I35: 0 | J35: 0 | K35: -330 | L35: -44 | M35: 0 | N35: 0 | O35: 0 | P35: 0 | Q35: 0
D36: Business Acquistion | F36: ₹ in Millions | H36: 0 | I36: 0 | J36: 0 | K36: 0 | L36: -2054.4 | M36: 0 | N36: 0 | O36: 0 | P36: 0 | Q36: 0
A37: x | C37: Cash Used in Investing Activities | F37: ₹ in Millions | H37: =SUM(H29:H36) -> -14351.3 | I37: =SUM(I29:I36) -> 1128.4 | J37: =SUM(J29:J36) -> -10085 | K37: =SUM(K29:K36) -> -12987.6 | L37: =SUM(L29:L36) -> -16672.1 | M37: =SUM(M29:M36) -> -1804.2572 | N37: =SUM(N29:N36) -> -3446.6325 | O37: =SUM(O29:O36) -> -3700.8406 | ... Q37: =SUM(Q29:Q36) -> -4206.965
C38: Cash Flow from Financing Activities
D39: Borrowings (net) | F39: ₹ in Millions | H39: 8627.8 | I39: -12784.8 | J39: -4808.9 | K39: -1941.1 | L39: 2486.1 | M39: =-Debt!M12+5900.4 -> 5565.4 | N39: =-Debt!N12 -> -1082.47 | O39: =-Debt!O12 -> -1082.47 | P39: =-Debt!P12 -> -853.9 | Q39: =-Debt!Q12 -> -853.9
D40: Proceeds from issue of compulsory convertible preferance shares | F40: ₹ in Millions | H40: 0 | I40: 1614.8 | J40: 0 | K40: 0 | L40: 0 | M40: 0 | N40: 0 | O40: 0 | P40: 0 | Q40: 0
...

Sheet Revenue Assumptions
C1: Revenue Driver | H1: Historicals | M1: Forecasted
E2: Constants | F2: Units | H2: 2022 | I2: =H2+1 -> 2023 | J2: =I2+1 -> 2024 | K2: =J2+1 -> 2025 | L2: =K2+1 -> 2026 | M2: =L2+1 -> 2027 | N2: =M2+1 -> 2028 | O2: =N2+1 -> 2029 | P2: =O2+1 -> 2030 | Q2: =P2+1 -> 2031
D3: Sales | E3: Scenario Slection | F3: ₹ in Million | H3: ='Income Statement'!H3 -> 106341.9 | I3: ='Income Statement'!I3 -> 115992.6 | J3: ='Income Statement'!J3 -> 126675.8 | K3: ='Income Statement'!K3 -> 129645.2 | L3: ='Income Statement'!L3 -> 147122.7 | M3: =L3*(1+M4) -> 159668.78 | N3: =M3*(1+N4) -> 172331.63 | O3: =N3*(1+O4) -> 185042.03 | P3: =O3*(1+P4) -> 197734.54 | Q3: =P3*(1+Q4) -> 210348.25
D4: Growth | E4: Base Case | F4: % | I4: =(I3/H3)-1 -> 0.090751623 | J4: =(J3/I3)-1 -> 0.092102427 | K4: =(K3/J3)-1 -> 0.023440941 | L4: =(L3/K3)-1 -> 0.13481024 | M4: =CHOOSE($E$5,M7:Q7,M8:Q8,M9:Q9) -> 0.085276307 | N4: =CHOOSE($E$5,N7:R7,N8:R8,N9:R9) -> 0.079306965 | O4: =CHOOSE($E$5,O7:S7,O8:S8,O9:S9) -> 0.073755478 | P4: =CHOOSE($E$5,P7:T7,P8:T8,P9:T9) -> 0.068592594 | Q4: =CHOOSE($E$5,Q7:U7,Q8:U8,Q9:U9) -> 0.063791113
E5: =IF(E4=D7,1,IF(E4=D8,2,3)) -> 1
D6: Sales Scenarios | F6: Growth
D7: Base Case | F7: =AVERAGE(I4:L4) -> 0.085276307 | M7: =F7 -> 0.085276307 | N7: =M7*(1-$F$10) -> 0.079306965 | O7: =N7*(1-$F$10) -> 0.073755478 | P7: =O7*(1-$F$10) -> 0.068592594 | Q7: =P7*(1-$F$10) -> 0.063791113
D8: Bull Case | F8: =MAX(I4:L4) -> 0.13481024 | M8: =F8 -> 0.13481024 | N8: =M8*(1-$F$10) -> 0.12537352 | O8: =N8*(1-$F$10) -> 0.11659737 | P8: =O8*(1-$F$10) -> 0.10843556 | Q8: =P8*(1-$F$10) -> 0.10084507
D9: Bear Case | F9: =MIN(I4:L4) -> 0.023440941 | M9: =F9 -> 0.023440941 | N9: =M9*(1-$F$10) -> 0.021800075 | O9: =N9*(1-$F$10) -> 0.02027407 | P9: =O9*(1-$F$10) -> 0.018854885 | Q9: =P9*(1-$F$10) -> 0.017535043
D10: Annual Growth Tampering | F10: 0.07
D12: CRISIL Assumption
D13: Crisil Ratings expects the revenue to grow by 8-10% annually, supported by new product launches and backed by price hikes undertaken across the product portfolio and its leadership position in key therapeutic areas.
D14: Ebitda margin narrowed by 140 basis points to 20.5% from 21.9% last year, indicating that expenses grew faster than revenue during the quarter.
D15: The decline in bottom-line profit was also driven by a sharp rise in tax expense, which increased to Rs 251 crore from Rs 103 crore in the corresponding quarter of the previous year.

Sheet Cost Assumptions
A1: Costing | H1: Historicals | M1: Forecasted
E2: Constants | F2: Units | H2: 2022 | I2: =H2+1 -> 2023 | J2: =I2+1 -> 2024 | K2: =J2+1 -> 2025 | L2: =K2+1 -> 2026 | M2: =L2+1 -> 2027 | N2: =M2+1 -> 2028 | O2: =N2+1 -> 2029 | P2: =O2+1 -> 2030 | Q2: =P2+1 -> 2031
C3: Sales | F3: ₹ in Millions | H3: ='Income Statement'!H3 -> 106341.9 | I3: ='Income Statement'!I3 -> 115992.6 | J3: ='Income Statement'!J3 -> 126675.8 | K3: ='Income Statement'!K3 -> 129645.2 | L3: ='Income Statement'!L3 -> 147122.7 | M3: ='Income Statement'!M3 -> 159668.78 | N3: ='Income Statement'!N3 -> 172331.63 | O3: ='Income Statement'!O3 -> 185042.03 | ... Q3: ='Income Statement'!Q3 -> 210348.25
D4: Cost of Materials Consumed | F4: ₹ in Millions | H4: =-'Income Statement'!H4 -> 32260.6 | I4: =-'Income Statement'!I4 -> 30569.2 | J4: =-'Income Statement'!J4 -> 32945.9 | K4: =-'Income Statement'!K4 -> 34403.7 | L4: =-'Income Statement'!L4 -> 35653.9 | M4: =M3*M12 -> 38320.507 | N4: =N3*N12 -> 41359.59 | O4: =O3*O12 -> 44410.087 | P4: =P3*P12 -> 47456.29 | Q4: =Q3*Q12 -> 50483.579
D5: Purchases of stock in trade | F5: ₹ in Millions | H5: =-'Income Statement'!H5 -> 14897.1 | I5: =-'Income Statement'!I5 -> 13875.5 | J5: =-'Income Statement'!J5 -> 16288.7 | K5: =-'Income Statement'!K5 -> 15140.2 | L5: =-'Income Statement'!L5 -> 16945.5 | M5: =M3*M13 -> 19160.254 | N5: =N3*N13 -> 20679.795 | O5: =O3*O13 -> 22205.043 | P5: =P3*P13 -> 23728.145 | Q5: =Q3*Q13 -> 25241.79
D6: Changes in Inventory | F6: ₹ in Millions | H6: ='Income Statement'!H6 -> 5354.8 | I6: ='Income Statement'!I6 -> -4623.7 | J6: ='Income Statement'!J6 -> -141.2 | K6: ='Income Statement'!K6 -> 1901.3 | L6: ='Income Statement'!L6 -> 1671.2 | M6: =M3*M14 -> 1437.019 | N6: =N3*N14 -> 1550.9846 | O6: =O3*O14 -> 1665.3783 | P6: =P3*P14 -> 1779.6109 | Q6: =Q3*Q14 -> 1893.1342
C7: Total of Cost of Good sold | F7: ₹ in Millions | H7: =SUM(H4:H6) -> 52512.5 | I7: =SUM(I4:I6) -> 39821 | J7: =SUM(J4:J6) -> 49093.4 | K7: =SUM(K4:K6) -> 51445.2 | L7: =SUM(L4:L6) -> 54270.6 | M7: =SUM(M4:M6) -> 58917.78 | N7: =SUM(N4:N6) -> 63590.37 | O7: =SUM(O4:O6) -> 68280.508 | ... Q7: =SUM(Q4:Q6) -> 77618.503
D8: Employee Expenses | F8: ₹ in Millions | H8: =-'Income Statement'!H9 -> 19627.1 | I8: =-'Income Statement'!I9 -> 21313.5 | J8: =-'Income Statement'!J9 -> 22010.1 | K8: =-'Income Statement'!K9 -> 24539.2 | L8: =-'Income Statement'!L9 -> 28371.1 | M8: =(M3*M$15) -> 30337.068 | N8: =(N3*N$15) -> 32743.009 | O8: =(O3*O$15) -> 35157.985 | P8: =(P3*P$15) -> 37569.563 | Q8: =(Q3*Q$15) -> 39966.167
D9: Operating Expenses | F9: ₹ in Millions | H9: =-'Income Statement'!H10 -> 24382.7 | I9: =-'Income Statement'!I10 -> 29516.2 | J9: =-'Income Statement'!J10 -> 32835 | K9: =-'Income Statement'!K10 -> 32341.9 | L9: =-'Income Statement'!L10 -> 37771.8 | M9: =(M3*M$16) -> 39917.195 | N9: =(N3*N$16) -> 43082.907 | O9: =(O3*O$16) -> 46260.507 | P9: =(P3*P$16) -> 49433.635 | Q9: =(Q3*Q$16) -> 52587.062
C10: Total Operating Expenses | F10: ₹ in Millions | H10: =SUM(H8:H9) -> 44009.8 | I10: =SUM(I8:I9) -> 50829.7 | J10: =SUM(J8:J9) -> 54845.1 | K10: =SUM(K8:K9) -> 56881.1 | L10: =SUM(L8:L9) -> 66142.9 | M10: =SUM(M8:M9) -> 70254.263 | N10: =SUM(N8:N9) -> 75825.916 | O10: =SUM(O8:O9) -> 81418.493 | ... Q10: =SUM(Q8:Q9) -> 92553.229
C11: Assumptions
D12: Cost of Materials Consumed as % of Sales | F12: % | H12: =(H4/H3) -> 0.30336678 | I12: =(I4/I3) -> 0.2635444 | J12: =(J4/J3) -> 0.26008046 | K12: =(K4/K3) -> 0.2653681 | L12: =(L4/L3) -> 0.24234126 | M12: 0.24 | N12: =M12 -> 0.24 | O12: =N12 -> 0.24 | P12: =O12 -> 0.24 | Q12: =P12 -> 0.24
D13: Purchases of stock in trade as % of Sales | F13: % | H13: =H5/H3 -> 0.14008683 | I13: =I5/I3 -> 0.11962401 | J13: =J5/J3 -> 0.12858573 | K13: =K5/K3 -> 0.1167818 | L13: =L5/L3 -> 0.11517937 | M13: 0.12 | N13: 0.12 | O13: 0.12 | P13: 0.12 | Q13: 0.12
D14: Changes in Inventory as % of Sales | F14: % | H14: =H6/H3 -> 0.050354564 | I14: =I6/I3 -> -0.039862026 | J14: =J6/J3 -> -0.0011146565 | K14: =K6/K3 -> 0.01466541 | L14: =L6/L3 -> 0.011359226 | M14: 0.009 | N14: 0.009 | O14: 0.009 | P14: 0.009 | Q14: 0.009
D15: Employee Expenses as % of Sales | F15: % | H15: =(H8/H3) -> 0.18456601 | I15: =(I8/I3) -> 0.18374879 | J15: =(J8/J3) -> 0.17375142 | K15: =(K8/K3) -> 0.18927966 | L15: =(L8/L3) -> 0.19283972 | M15: 0.19 | N15: 0.19 | O15: 0.19 | P15: 0.19 | Q15: 0.19
D16: Operating Expenses as % of Sales | F16: % | H16: =(H9/H3) -> 0.22928592 | I16: =(I9/I3) -> 0.25446623 | J16: =(J9/J3) -> 0.25920499 | K16: =(K9/K3) -> 0.24946469 | L16: =(L9/L3) -> 0.25673672 | M16: 0.25 | N16: 0.25 | O16: 0.25 | P16: 0.25 | Q16: 0.25

Sheet Working Capital
A1: Working Capital | H1: Historicals | M1: Forecasted
E2: Constants | F2: Units | H2: 2022 | I2: =H2+1 -> 2023 | J2: =I2+1 -> 2024 | K2: =J2+1 -> 2025 | L2: =K2+1 -> 2026 | M2: =L2+1 -> 2027 | N2: =M2+1 -> 2028 | O2: =N2+1 -> 2029 | P2: =O2+1 -> 2030 | Q2: =P2+1 -> 2031
D3: Revenue | F3: ₹ in Millions | H3: ='Income Statement'!H3 -> 106341.9 | I3: ='Income Statement'!I3 -> 115992.6 | J3: ='Income Statement'!J3 -> 126675.8 | K3: ='Income Statement'!K3 -> 129645.2 | L3: ='Income Statement'!L3 -> 147122.7 | M3: ='Income Statement'!M3 -> 159668.78 | N3: ='Income Statement'!N3 -> 172331.63 | O3: ='Income Statement'!O3 -> 185042.03 | ... Q3: ='Income Statement'!Q3 -> 210348.25
D4: Cost of Goods Sold | F4: ₹ in Millions | H4: =-'Income Statement'!H7 -> 41802.9 | I4: =-'Income Statement'!I7 -> 49068.4 | J4: =-'Income Statement'!J7 -> 49375.8 | K4: =-'Income Statement'!K7 -> 47642.6 | L4: =-'Income Statement'!L7 -> 50928.2 | M4: =-'Income Statement'!M7 -> 58917.78 | N4: =-'Income Statement'!N7 -> 63590.37 | O4: =-'Income Statement'!O7 -> 68280.508 | ... Q4: =-'Income Statement'!Q7 -> 77618.503
D5: Accounts Receivable | F5: ₹ in Millions | H5: ='Balance sheet'!H6 -> 18846 | I5: ='Balance sheet'!I6 -> 21321.8 | J5: ='Balance sheet'!J6 -> 22528.1 | K5: ='Balance sheet'!K6 -> 24662.5 | L5: ='Balance sheet'!L6 -> 29791.1 | M5: =(M3*M11)/365 -> 31933.756 | N5: =(N3*N11)/365 -> 34466.325 | O5: =(O3*O11)/365 -> 37008.406 | P5: =(P3*P11)/365 -> 39546.908 | Q5: =(Q3*Q11)/365 -> 42069.65
D6: Inventory | F6: ₹ in Millions | H6: ='Balance sheet'!H7 -> 30055.3 | I6: ='Balance sheet'!I7 -> 26075.3 | J6: ='Balance sheet'!J7 -> 26611.8 | K6: ='Balance sheet'!K7 -> 29224.1 | L6: ='Balance sheet'!L7 -> 33332.2 | M6: =(M4*M12)/365 -> 37933.365 | N6: =(N4*N12)/365 -> 40941.745 | O6: =(O4*O12)/365 -> 43961.423 | P6: =(P4*P12)/365 -> 46976.851 | Q6: =(Q4*Q12)/365 -> 49973.557
D7: Accounts Payables | F7: ₹ in Millions | H7: ='Balance sheet'!H30 -> 11733.8 | I7: ='Balance sheet'!I30 -> 11650.3 | J7: ='Balance sheet'!J30 -> 17481.2 | K7: ='Balance sheet'!K30 -> 18393.5 | L7: ='Balance sheet'!L30 -> 22441.8 | M7: =(M4*M13)/365 -> 25988.391 | N7: =(N4*N13)/365 -> 28049.451 | O7: =(O4*O13)/365 -> 30118.252 | P7: =(P4*P13)/365 -> 32184.141 | Q7: =(Q4*Q13)/365 -> 34237.203
D8: Net Woring Capital | F8: ₹ in Millions | H8: =SUM(H5:H6)-H7 -> 37167.5 | I8: =SUM(I5:I6)-I7 -> 35746.8 | J8: =SUM(J5:J6)-J7 -> 31658.7 | K8: =SUM(K5:K6)-K7 -> 35493.1 | L8: =SUM(L5:L6)-L7 -> 40681.5 | M8: =SUM(M5:M6)-M7 -> 43878.731 | N8: =SUM(N5:N6)-N7 -> 47358.62 | O8: =SUM(O5:O6)-O7 -> 50851.577 | ... Q8: =SUM(Q5:Q6)-Q7 -> 57806.004
D9: Changes in Working Captial | F9: ₹ in Millions | I9: =H8-I8 -> 1420.7 | J9: =I8-J8 -> 4088.1 | K9: =J8-K8 -> -3834.4 | L9: =K8-L8 -> -5188.4 | M9: =L8-M8 -> -3197.2307 | N9: =M8-N8 -> -3479.889 | O9: =N8-O8 -> -3492.9576 | P9: =O8-P8 -> -3488.0416 | Q9: =P8-Q8 -> -3466.3848
C10: Assumptions
D11: Days Sales Outstanding (DSO) | F11: Days | H11: =(H5/H3)*365 -> 64.685604 | I11: =(I5/I3)*365 -> 67.094427 | J11: =(J5/J3)*365 -> 64.911818 | K11: =(K5/K3)*365 -> 69.434214 | L11: =(L5/L3)*365 -> 73.909407 | M11: 73 | N11: 73 | O11: 73 | P11: 73 | Q11: 73
D12: Days Inventory Outstanding (DIO) | F12: Days | H12: =(H6/H$4)*365 -> 262.4264 | I12: =(I6/I$4)*365 -> 193.96362 | J12: =(J6/J$4)*365 -> 196.72202 | K12: =(K6/K$4)*365 -> 223.89199 | L12: =(L6/L$4)*365 -> 238.8903 | M12: 235 | N12: 235 | O12: 235 | P12: 235 | Q12: 235
D13: Days Payable Outstanding (DPO) | F13: Days | H13: =(H7/H$4)*365 -> 102.45311 | I13: =(I7/I$4)*365 -> 86.661874 | J13: =(J7/J$4)*365 -> 129.22602 | K13: =(K7/K$4)*365 -> 140.91648 | L13: =(L7/L$4)*365 -> 160.83932 | M13: =161 -> 161 | N13: =161 -> 161 | O13: =161 -> 161 | P13: =161 -> 161 | Q13: =161 -> 161
D14: Cash Conversion Cycles | F14: Days | H14: =SUM(H11:H12)-H13 -> 224.6589 | I14: =SUM(I11:I12)-I13 -> 174.39617 | J14: =SUM(J11:J12)-J13 -> 132.40782 | K14: =SUM(K11:K12)-K13 -> 152.40972 | L14: =SUM(L11:L12)-L13 -> 151.96039 | M14: =SUM(M11:M12)-M13 -> 147 | N14: =SUM(N11:N12)-N13 -> 147 | O14: =SUM(O11:O12)-O13 -> 147 | ... Q14: =SUM(Q11:Q12)-Q13 -> 147

Sheet Debt
A1: Debt | H1: Historicals | M1: Forecasted
E2: Constants | F2: Units | H2: 2022 | I2: =H2+1 -> 2023 | J2: =I2+1 -> 2024 | K2: =J2+1 -> 2025 | L2: =K2+1 -> 2026 | M2: =L2+1 -> 2027 | N2: =M2+1 -> 2028 | O2: =N2+1 -> 2029 | P2: =O2+1 -> 2030 | Q2: =P2+1 -> 2031 | R2: 2027 | S2: =1+R2 -> 2028 | T2: =1+S2 -> 2029 | U2: =1+T2 -> 2030 | V2: =1+U2 -> 2031 | W2: Loan | X2: EQI | Y2: Quaterly
D3: Opening Debt | F3: ₹ in Millions | I3: =H6 -> 25801.2 | J3: =I6 -> 13071.5 | K3: =J6 -> 12139.7 | L3: =K6 -> 10627.9 | M3: =L6 -> 16235 | N3: =M6 -> 15900 | O3: =N6 -> 14817.53 | P3: =O6 -> 13735.06 | Q3: =P6 -> 12881.16 | R3: 228.57 | S3: 228.57 | T3: 228.57 | U3: 0 | V3: 0 | W3: 800 | X3: 14 | Y3: =W3/X3 -> 57.142857
D4: Additons | F4: ₹ in Millions | M4: 0 | N4: 0 | O4: 0 | P4: 0 | Q4: 0 | R4: 106.43 | S4: 425.72 | T4: 425.72 | U4: 425.72 | V4: 425.72 | W4: 2128.6 | X4: 20 | Y4: =W4/X4 -> 106.43
D5: (Repayments) | F5: ₹ in Millions | M5: =-R6 -> -335 | N5: =-S6 -> -1082.47 | O5: =-T6 -> -1082.47 | P5: =-U6 -> -853.9 | Q5: =-V6 -> -853.9 | R5: 0 | S5: 428.18 | T5: 428.18 | U5: 428.18 | V5: 428.18 | W5: 2140.9 | X5: 20 | Y5: =W5/X5 -> 107.045
D6: Ending Debt | F6: ₹ in Millions | H6: =SUM('Balance sheet'!H40,'Balance sheet'!H31) -> 25801.2 | I6: =SUM('Balance sheet'!I40,'Balance sheet'!I31) -> 13071.5 | J6: =SUM('Balance sheet'!J40,'Balance sheet'!J31) -> 12139.7 | K6: =SUM('Balance sheet'!K40,'Balance sheet'!K31) -> 10627.9 | L6: =SUM('Balance sheet'!L40,'Balance sheet'!L31) -> 16235 | M6: =SUM(M3:M5) -> 15900 | N6: =SUM(N3:N5) -> 14817.53 | O6: =SUM(O3:O5) -> 13735.06 | P6: =SUM(P3:P5) -> 12881.16 | Q6: =SUM(Q3:Q5) -> 12027.26 | R6: =SUM(R3:R5) -> 335 | S6: =SUM(S3:S5) -> 1082.47 | T6: =SUM(T3:T5) -> 1082.47 | ... W6: =SUM(W3:W5) -> 5069.5
D8: Interest Expenses | F8: ₹ in Millions | H8: ='Income Statement'!H14 -> -523.7 | I8: ='Income Statement'!I14 -> -1073.6 | J8: ='Income Statement'!J14 -> -1124.1 | K8: ='Income Statement'!K14 -> -1217 | L8: ='Income Statement'!L14 -> -1607.8 | M8: =-M3*M9 -> -1461.15 | N8: =-N3*N9 -> -1431 | O8: =-O3*O9 -> -1333.5777 | P8: =-P3*P9 -> -1236.1554 | Q8: =-Q3*Q9 -> -1159.3044
D9: Interest Rate | F9: % | I9: =-I8/AVERAGE(I3,I6) -> 0.055236709 | J9: =-J8/AVERAGE(J3,J6) -> 0.089174653 | K9: =-K8/AVERAGE(K3,K6) -> 0.10690631 | L9: =-L8/AVERAGE(L3,L6) -> 0.11970413 | M9: 0.09 | N9: =M9 -> 0.09 | O9: =N9 -> 0.09 | P9: =O9 -> 0.09 | Q9: =P9 -> 0.09
D11: Revolver Credit | F11: ₹ in Millions | L11: 10852.5 | M11: =L11 -> 10852.5 | N11: =M11 -> 10852.5 | O11: =N11 -> 10852.5 | P11: =O11 -> 10852.5 | Q11: =P11 -> 10852.5
D12: Current Maturities of Long term debt | F12: ₹ in Millions | L12: 458 | M12: =-M5 -> 335 | N12: =-N5 -> 1082.47 | O12: =-O5 -> 1082.47 | P12: =-P5 -> 853.9 | Q12: =-Q5 -> 853.9
D13: Total Short term debt | F13: ₹ in Millions | L13: =SUM(L11:L12) -> 11310.5 | M13: =SUM(M11:M12) -> 11187.5 | N13: =SUM(N11:N12) -> 11934.97 | O13: =SUM(O11:O12) -> 11934.97 | P13: =SUM(P11:P12) -> 11706.4 | Q13: =SUM(Q11:Q12) -> 11706.4
D14: Long Term Debt | F14: ₹ in Millions | L14: ='Balance sheet'!L40 -> 4924.5 | M14: =M6-M13 -> 4712.5 | N14: =N6-N13 -> 2882.56 | O14: =O6-O13 -> 1800.09 | P14: =P6-P13 -> 1174.76 | Q14: =Q6-Q13 -> 320.86
D15: Total Debt | F15: ₹ in Millions | L15: =SUM(L13:L14) -> 16235 | M15: =SUM(M13:M14) -> 15900 | N15: =SUM(N13:N14) -> 14817.53 | O15: =SUM(O13:O14) -> 13735.06 | P15: =SUM(P13:P14) -> 12881.16 | Q15: =SUM(Q13:Q14) -> 12027.26

Sheet Depreciation & Amortisation
A1: Depreciation & Amortisation | H1: Historicals | M1: Forecasted
E2: Constants | F2: Units | H2: 2022 | I2: =H2+1 -> 2023 | J2: =I2+1 -> 2024 | K2: =J2+1 -> 2025 | L2: =K2+1 -> 2026 | M2: =L2+1 -> 2027 | N2: =M2+1 -> 2028 | O2: =N2+1 -> 2029 | P2: =O2+1 -> 2030 | Q2: =P2+1 -> 2031
C3: Net Sales | F3: ₹ in Millions | H3: ='Income Statement'!H3 -> 106341.9 | I3: ='Income Statement'!I3 -> 115992.6 | J3: ='Income Statement'!J3 -> 126675.8 | K3: ='Income Statement'!K3 -> 129645.2 | L3: ='Income Statement'!L3 -> 147122.7 | M3: ='Income Statement'!M3 -> 159668.78 | N3: ='Income Statement'!N3 -> 172331.63 | O3: ='Income Statement'!O3 -> 185042.03 | ... Q3: ='Income Statement'!Q3 -> 210348.25
D4: Capital Expenditures | F4: ₹ in Millions | H4: =SUM('Cash Flow Statement'!H29:H30) -> -3279.8 | I4: =SUM('Cash Flow Statement'!I29:I30) -> -2297.1 | J4: =SUM('Cash Flow Statement'!J29:J30) -> -1868.1 | K4: =SUM('Cash Flow Statement'!K29:K30) -> -6347.8 | L4: =SUM('Cash Flow Statement'!L29:L30) -> -4869.5 | M4: =M3*M5 -> 1804.2572 | N4: =N3*N5 -> 3446.6325 | O4: =O3*O5 -> 3700.8406 | P4: =P3*P5 -> 3954.6908 | Q4: =Q3*Q5 -> 4206.965
D5: Capital Expenditures as % of Sales | F5: % | H5: =-H4/H3 -> 0.030842029 | I5: =-I4/I3 -> 0.01980385 | J5: =-J4/J3 -> 0.014747095 | K5: =-K4/K3 -> 0.048962862 | L5: =-L4/L3 -> 0.033098223 | M5: 0.0113 | N5: 0.02 | O5: =N5 -> 0.02 | P5: =O5 -> 0.02 | Q5: =P5 -> 0.02
D7: Beginning Net PP&E | F7: ₹ in Million | M7: =L11 -> 26949.7 | N7: =M11 -> 24607.551 | O7: =N11 -> 23578.938 | P7: =O11 -> 22474.459 | Q7: =P11 -> 21294.221
D8: Capital Expenditures | F8: ₹ in Million | M8: =M4 -> 1804.2572 | N8: =N4 -> 3446.6325 | O8: =O4 -> 3700.8406 | P8: =P4 -> 3954.6908 | Q8: =Q4 -> 4206.965
D9: (Depreciation Expense) | F9: ₹ in Million | H9: ='Income Statement'!H12 -> -3039.6 | I9: ='Income Statement'!I12 -> -3104.2 | J9: ='Income Statement'!J12 -> -2993 | K9: ='Income Statement'!K12 -> -3571.6 | L9: ='Income Statement'!L12 -> -3820.6 | M9: =-M3*M13 -> -4146.4067 | N9: =-N3*N13 -> -4475.2456 | O9: =-O3*O13 -> -4805.3195 | P9: =-P3*P13 -> -5134.9288 | Q9: =-Q3*Q13 -> -5462.4916
D10: (Asset Sales ) | F10: ₹ in Million | M10: 0 | N10: 0 | O10: 0 | P10: 0 | Q10: 0
C11: Ending Net PP&E | F11: ₹ in Millions | H11: ='Balance sheet'!H15 -> 22871 | I11: ='Balance sheet'!I15 -> 20654 | J11: ='Balance sheet'!J15 -> 21614.6 | K11: ='Balance sheet'!K15 -> 20639.3 | L11: ='Balance sheet'!L15 -> 26949.7 | M11: =SUM(M7:M10) -> 24607.551 | N11: =SUM(N7:N10) -> 23578.938 | O11: =SUM(O7:O10) -> 22474.459 | P11: =SUM(P7:P10) -> 21294.221 | Q11: =SUM(Q7:Q10) -> 20038.694
D13: Depreciation as % of Sales | F13: % | H13: =-H9/H3 -> 0.028583277 | I13: =-I9/I3 -> 0.026762052 | J13: =-J9/J3 -> 0.023627244 | K13: =-K9/K3 -> 0.027549034 | L13: =-L9/L3 -> 0.0259688 | M13: =L13 -> 0.0259688 | N13: =M13 -> 0.0259688 | O13: =N13 -> 0.0259688 | P13: =O13 -> 0.0259688 | Q13: =P13 -> 0.0259688
D15: Capex & Acqusition
D16: On February 13, 2026, Alkem, through its wholly owned subsidiary Alkem Medtech Pvt. Ltd., offered to acquire up to 55% stake in Occlutech Holding AG at an implied equity valuation of EUR 180.7 million (~Rs. 1,952 crore). The proposed acquisition would entail an estimated cash outflow of ~Rs. 1,100 crore and is proposed to be funded entirely through internal accruals and cash on hand. Crisil Ratings believes that with the proposed acquisition (~Rs 1,100 crore) and ongoing capex plans of ~Rs 700 crore, Alkem is expected to maintain comfortable liquidity and moderate leverage metrics, underpinned by its healthy cash generation from operations.

Sheet DCF
A1: DCF Valuation
C3: Assumptions
D4: Transaction Date | E4: 46279
D5: Fiscal Year End Date | E5: 46477
D6: Tax Rate | E6: ='Income Statement'!M31 -> 0.31
D7: EV/EBITDA | E7: ='Relative Valuation'!P13 -> 32.941495
D8: Growth Rate | E8: 0.03
D9: Discount Rate | E9: =WACC!E39 -> 0.074760432
D10: Shares Outstanding (million) | E10: ='Income Statement'!L33 -> 119.565
D12: Discounted Cash Flows | G12: Entry | H12: 2027 | I12: =H12+1 -> 2028 | J12: =I12+1 -> 2029 | K12: =J12+1 -> 2030 | L12: =K12+1 -> 2031 | M12: Exit
D13: Date | G13: =E4 -> 46279 | H13: =E5 -> 46477 | I13: 46843 | J13: 47208 | K13: 47573 | L13: 47938 | M13: 47938
D14: Time Period | H14: 0 | I14: =H14+1 -> 1 | J14: =I14+1 -> 2 | K14: =J14+1 -> 3 | L14: =K14+1 -> 4
D15: Yearfrac. | H15: =YEARFRAC(G13,H13) -> 0.54722222 | I15: =YEARFRAC(H13,I13) -> 1 | J15: =YEARFRAC(I13,J13) -> 1 | K15: =YEARFRAC(J13,K13) -> 1 | L15: =YEARFRAC(K13,L13) -> 1 | M15: =L15 -> 1
D17: EBIT | H17: ='Income Statement'!M13 -> 26350.33 | I17: ='Income Statement'!N13 -> 28440.095 | J17: ='Income Statement'!O13 -> 30537.708 | K17: ='Income Statement'!P13 -> 32632.369 | L17: ='Income Statement'!Q13 -> 34714.024
D18: Less: Taxes | H18: =-H17*$E$6 -> -8168.6024 | I18: =-I17*$E$6 -> -8816.4295 | J18: =-J17*$E$6 -> -9466.6895 | K18: =-K17*$E$6 -> -10116.034 | L18: =-L17*$E$6 -> -10761.347 | N18: Terminal Value
D19: NOPAT | H19: =SUM(H17:H18) -> 18181.728 | I19: =SUM(I17:I18) -> 19623.666 | J19: =SUM(J17:J18) -> 21071.018 | K19: =SUM(K17:K18) -> 22516.334 | L19: =SUM(L17:L18) -> 23952.676 | N19: EV/EBITDA | O19: =(L17+L20)*E7 -> 1323474.5
D20: Add: Depreciation & Amortization | H20: ='Cash Flow Statement'!M6 -> 4146.4067 | I20: ='Cash Flow Statement'!N6 -> 4475.2456 | J20: ='Cash Flow Statement'!O6 -> 4805.3195 | K20: ='Cash Flow Statement'!P6 -> 5134.9288 | L20: ='Cash Flow Statement'!Q6 -> 5462.4916 | N20: Perpetuity | O20: =L23*(1+E8)/(E9-E8) -> 500309.58
D21: Less: Capex | H21: ='Cash Flow Statement'!M29 -> -1804.2572 | I21: ='Cash Flow Statement'!N29 -> -3446.6325 | J21: ='Cash Flow Statement'!O29 -> -3700.8406 | K21: ='Cash Flow Statement'!P29 -> -3954.6908 | L21: ='Cash Flow Statement'!Q29 -> -4206.965 | N21: Average | O21: =AVERAGE(O19:O20) -> 911892.02
D22: Less: Changes in Working Capital | H22: =SUM('Cash Flow Statement'!M21,'Cash Flow Statement'!M23,'Cash Flow Statement'!M24) -> -3197.2307 | I22: =SUM('Cash Flow Statement'!N21,'Cash Flow Statement'!N23,'Cash Flow Statement'!N24) -> -3479.889 | J22: =SUM('Cash Flow Statement'!O21,'Cash Flow Statement'!O23,'Cash Flow Statement'!O24) -> -3492.9576 | K22: =SUM('Cash Flow Statement'!P21,'Cash Flow Statement'!P23,'Cash Flow Statement'!P24) -> -3488.0416 | L22: =SUM('Cash Flow Statement'!Q21,'Cash Flow Statement'!Q23,'Cash Flow Statement'!Q24) -> -3466.3848
D23: Free Cash Flow to Firm | H23: =SUM(H19:H22) -> 17326.647 | I23: =SUM(I19:I22) -> 17172.39 | J23: =SUM(J19:J22) -> 18682.54 | K23: =SUM(K19:K22) -> 20208.531 | L23: =SUM(L19:L22) -> 21741.818 | M23: =O21 -> 911892.02
D25: Transaction FCFF | H25: =H23*H15 -> 9481.5261 | I25: =I23*I15 -> 17172.39 | J25: =J23*J15 -> 18682.54 | K25: =K23*K15 -> 20208.531 | L25: =L23*L15 -> 21741.818 | M25: =M23*M15 -> 911892.02
D27: Intrinsic Value | G27: Rate of Return
D28: Enterprise Value | E28: =XNPV(E9,H25:M25,H13:M13) -> 757492.46 | G28: Current Price | I28: 5089
D29: Add: Cash & Cash Eq | E29: =SUM('Balance sheet'!M4:M5) -> 32104.206 | G29: Target Price | I29: =E34 -> 6423.898
D30: Less: Debt | E30: =-Debt!L15 -> -16235 | G30: Upside Potential | I30: =I29/I28-1 -> 0.26231047
D31: Less: Non-Controlling Interest | E31: =-'Balance sheet'!L50 -> -5288.3
D32: Equity Value | E32: =SUM(E28:E31) -> 768073.36
D34: Intrinsic Value per Share | E34: =E32/E10 -> 6423.898
C36: Sensitivity Analysis
J37: Exit Multiples
J38: =E34 -> 6423.898 | K38: 27.9 | L38: 30.4 | M38: 32.9 | N38: 35.4 | O38: 37.9
I39: Discount Rate | J39: 0.0548 | K39: 7571.4106 | L39: 7910.6718 | M39: 8249.9331 | N39: 8589.1943 | O39: 8928.4556
J40: 0.0648 | K40: 6460.6933 | L40: 6787.3799 | M40: 7114.0665 | N40: 7440.7531 | O40: 7767.4397
J41: 0.0748 | K41: 5787.02 | L41: 6101.7091 | M41: 6416.3983 | N41: 6731.0874 | O41: 7045.7766
J42: 0.0848 | K42: 5314.4269 | L42: 5617.6643 | M42: 5920.9016 | N42: 6224.1389 | O42: 6527.3762
J43: 0.0948 | K43: 4952.4057 | L43: 5244.7074 | M43: 5537.009 | N43: 5829.3107 | O43: 6121.6124
J45: Perpectual Growth
J46: =E34 -> 6423.898 | K46: 0.02 | L46: 0.025 | M46: 0.03 | N46: 0.035 | O46: 0.04
I47: Discount Rate | J47: 0.0548 | K47: 7358.0174 | L47: 7731.4932 | M47: 8255.5641 | N47: 9044.3172 | O47: 10366.012
J48: 0.0648 | K48: 6636.5126 | L48: 6847.663 | M48: 7119.4888 | N48: 7482.5313 | O48: 7991.9619
...

Sheet Relative Valuation
A1: Comparable Company Analysis | O1: Except Share price in Crore
F2: Market Data | L2: Financial Data | O2: Valuation
D3: Company | E3: Ticker | F3: CMP | G3: Shares in crore | H3: Market Cap | I3: Debt | J3: Cash | K3: EV | L3: Sales | M3: EBITDA | N3: Net Income | O3: EV/Sales | P3: EV/EBITDA | Q3: P/E
D4: Sun Pharma.Inds. | E4: SUNPHARMA | F4: 1875.35 | G4: 239.93 | H4: 449952.73 | I4: 4627.32 | J4: 11603.08 | K4: 442976.97 | L4: 19709.57 | M4: 12632.59 | N4: 12632.59 | O4: 22.475222 | P4: 35.066203 | Q4: 35.618406
D5: Divi's Lab. | E5: DIVISLAB | F5: 9489.7 | G5: 26.55 | H5: 251951.54 | I5: 7 | J5: 3414 | K5: 248544.54 | L5: 3949 | M5: 2979.27 | N5: 2979.27 | O5: 62.938601 | P5: 83.424643 | Q5: 84.568211
D6: Torrent Pharma. | E6: TORNTPHARM | F6: 4951.2 | G6: 33.84 | H6: 167548.61 | I6: 15025.5 | J6: 1165.2 | K6: 181408.91 | L6: 4416.28 | M6: 2231.18 | N6: 2231.18 | O6: 41.077311 | P6: 81.306263 | Q6: 75.094169
D7: Zydus Lifesci. | E7: ZUDUSLIFE | F7: 1137.7 | G7: 100.62 | H7: 114475.37 | I7: 12496 | J7: 1416.6 | K7: 125554.77 | L7: 8982.3 | M7: 4868.59 | N7: 4868.59 | O7: 13.978021 | P7: 25.788734 | Q7: 23.513045
D8: Cipla | E8: CILPA | F8: 1374.3 | G8: 80.76 | H8: 110988.47 | I8: 613.77 | J8: 1307.42 | K8: 110294.82 | L8: 6388.29 | M8: 3579.05 | N8: 3579.05 | O8: 17.265155 | P8: 30.816786 | Q8: 31.010594
D9: Laurus Labs | E9: LAURUSLABS | F9: 1931.65 | G9: 53.93 | H9: 104173.88 | I9: 2518.48 | J9: 113.7 | K9: 106578.66 | L9: 1840.14 | M9: 1093.37 | N9: 1093.37 | O9: 57.91878 | P9: 97.477217 | Q9: 95.277797
D10: Aurobindo Pharma | E10: AUROPHARMA | F10: 1677.2 | G10: 58.08 | H10: 97411.776 | I10: 8072.84 | J10: 9870.29 | K10: 95614.326 | L10: 7362.22 | M10: 3780.97 | N10: 3780.97 | O10: 12.98716 | P10: 25.288306 | Q10: 25.7637
D12: Average | O12: =AVERAGE(O4:O15) -> 29.554639 | P12: =AVERAGE(P4:P15) -> 48.845298 | Q12: =AVERAGE(Q4:Q15) -> 47.946688
D13: Median | O13: 19.94224 | P13: 32.941495 | Q13: 33.3145
D15: Alkem Lab | E15: ALKEM | F15: 5199.5 | G15: 11.96 | H15: 62186.02 | I15: 2047.16 | J15: 1732.9 | K15: 62500.28 | L15: 3590.06 | M15: 2272.9 | N15: 2272.9 | O15: 17.409258 | P15: 27.498033 | Q15: 27.359769
D17: Metric | E17: Industry Median | F17: EV | G17: Net Debt | H17: Equity Value | I17: Shares | J17: Share Price
D18: EV/Sales | E18: =O13 -> 19.94224 | F18: =E18*L15 -> 71593.838 | G18: =I15-J15 -> 314.26 | H18: =F18-G18 -> 71279.578 | I18: =G15 -> 11.96 | J18: =H18/I18 -> 5959.8309
D19: EV/EBITDA | E19: =P13 -> 32.941495 | F19: =E19*M15 -> 74872.723 | G19: =G18 -> 314.26 | H19: =F19-G19 -> 74558.463 | I19: =I18 -> 11.96 | J19: =H19/I19 -> 6233.9852
D20: P/E | E20: =Q13 -> 33.3145 | F20: =G20+H20 -> 76034.788 | G20: =G18 -> 314.26 | H20: =E20*N15 -> 75720.528 | I20: =I18 -> 11.96 | J20: =H20/I20 -> 6331.1478
C22: Input Data
H23: ₹ in Crore
D24: Company | E24: Ticker | F24: CMP in ₹ | G24: No.of Shares | H24: Market Cap | I24: Debt | J24: Cash | K24: Sales | L24: EBITDA | M24: Net Income
D25: Sun Pharma.Inds. | E25: SUNPHARMA | F25: 1875.35 | G25: 239.93 | H25: 449959.27 | I25: 4627.32 | J25: 11603.08 | K25: 59910.52 | L25: 19709.57 | M25: 12632.59
D26: Divi's Lab. | E26: DIVISLAB | F26: 9489.7 | G26: 26.55 | H26: 251921.74 | I26: 7 | J26: 3414 | K26: 11230 | L26: 3949 | M26: 2979.27
D27: Torrent Pharma. | E27: TORNTPHARM | F27: 4951.2 | G27: 33.84 | H27: 188327.75 | I27: 15025.5 | J27: 1165.2 | K27: 15723 | L27: 4416.28 | M27: 2231.18
D28: Zydus Lifesci. | E28: ZUDUSLIFE | F28: 1137.7 | G28: 100.62 | H28: 113485.99 | I28: 12496 | J28: 1416.6 | K28: 28591.7 | L28: 8982.3 | M28: 4868.59
D29: Cipla | E29: CILPA | F29: 1374.3 | G29: 80.76 | H29: 111023.92 | I29: 613.77 | J29: 1307.42 | K29: 28324.4 | L29: 6388.29 | M29: 3579.05
D30: Laurus Labs | E30: LAURUSLABS | F30: 1931.65 | G30: 53.93 | H30: 104369.42 | I30: 2518.48 | J30: 113.7 | K30: 7269.64 | L30: 1840.14 | M30: 1093.37
D31: Aurobindo Pharma | E31: AUROPHARMA | F31: 1677.2 | G31: 58.08 | H31: 96502.38 | I31: 8072.84 | J31: 9870.29 | K31: 34935.29 | L31: 7362.22 | M31: 3780.97
D32: Alkem Lab | E32: ALKEM | F32: 5199.5 | G32: 11.96 | H32: 62167.79 | I32: 2047.16 | J32: 1732.9 | K32: 15081.28 | L32: 3590.06 | M32: 2272.9

Sheet Summary
A1: Football Field Chart | J1: Valuation Summary
B2: Foodball Field Data
E4: Relative Valuation | F4: DCF | G4: 52 Week High & Low | H4: Other Consensus
D5: High | E5: =MAX('Relative Valuation'!J18:J20) -> 6331.1478 | F5: 7513.1 | G5: 5933.5 | H5: 6850
D6: High | E6: =E5 -> 6331.1478 | F6: =F5 -> 7513.1 | G6: =G5 -> 5933.5 | H6: =H5 -> 6850
D7: Low | E7: =MIN('Relative Valuation'!J18:J20) -> 5959.8309 | F7: 5253.75 | G7: 5051 | H7: 4590
D8: Low | E8: =MIN('Relative Valuation'!J19:J21) -> 6233.9852 | F8: 5253.75 | G8: 5051 | H8: 4590

Sheet WACC
A1: WACC Calculation | L1: ₹ in Crore
D3: Company | E3: Ticker | F3: Maket Cap | G3: Debt | H3: Debt/Equity | I3: Debt/ Capital | J3: Tax Rate | K3: Levered Beta | L3: Unlevered Beta
D4: Sun Pharma.Inds. | E4: SUNPHARMA | F4: ='Relative Valuation'!H25 -> 449959.27 | G4: ='Relative Valuation'!I25 -> 4627.32 | H4: =G4/F4 -> 0.010283864 | I4: =G4/SUM(F4:G4) -> 0.010179183 | J4: 0.3 | K4: 0.48 | L4: =K4/(1+H4*(1-J4)) -> 0.47656932
D5: Divi's Lab. | E5: DIVISLAB | F5: ='Relative Valuation'!H26 -> 251921.74 | G5: ='Relative Valuation'!I26 -> 7 | H5: =G5/F5 -> 2.7786407e-05 | I5: =G5/SUM(F5:G5) -> 2.7785635e-05 | J5: 0.3 | K5: 0.59 | L5: =K5/(1+H5*(1-J5)) -> 0.58998852
D6: Torrent Pharma. | E6: TORNTPHARM | F6: ='Relative Valuation'!H27 -> 188327.75 | G6: ='Relative Valuation'!I27 -> 15025.5 | H6: =G6/F6 -> 0.079783781 | I6: =G6/SUM(F6:G6) -> 0.073888664 | J6: 0.3 | K6: 0.23 | L6: =K6/(1+H6*(1-J6)) -> 0.21783425
D7: Zydus Lifesci. | E7: ZUDUSLIFE | F7: ='Relative Valuation'!H28 -> 113485.99 | G7: ='Relative Valuation'!I28 -> 12496 | H7: =G7/F7 -> 0.11011051 | I7: =G7/SUM(F7:G7) -> 0.099188781 | J7: 0.3 | K7: 0.66 | L7: =K7/(1+H7*(1-J7)) -> 0.61276936
D8: Cipla | E8: CILPA | F8: ='Relative Valuation'!H29 -> 111023.92 | G8: ='Relative Valuation'!I29 -> 613.77 | H8: =G8/F8 -> 0.0055282681 | I8: =G8/SUM(F8:G8) -> 0.0054978744 | J8: 0.3 | K8: 0.6 | L8: =K8/(1+H8*(1-J8)) -> 0.59768708
D9: Laurus Labs | E9: LAURUSLABS | F9: ='Relative Valuation'!H30 -> 104369.42 | G9: ='Relative Valuation'!I30 -> 2518.48 | H9: =G9/F9 -> 0.02413044 | I9: =G9/SUM(F9:G9) -> 0.023561881 | J9: 0.3 | K9: 0.84 | L9: =K9/(1+H9*(1-J9)) -> 0.82604699
D10: Aurobindo Pharma | E10: AUROPHARMA | F10: ='Relative Valuation'!H31 -> 96502.38 | G10: ='Relative Valuation'!I31 -> 8072.84 | H10: =G10/F10 -> 0.08365431 | I10: =G10/SUM(F10:G10) -> 0.077196491 | J10: 0.3 | K10: 0.37 | L10: =K10/(1+H10*(1-J10)) -> 0.34953209
D12: Average | H12: =AVERAGE(H4:H10) -> 0.044788422 | I12: =AVERAGE(I4:I10) -> 0.041362951 | J12: =AVERAGE(J4:J10) -> 0.3 | K12: =AVERAGE(K4:K10) -> 0.53857143 | L12: =AVERAGE(L4:L10) -> 0.5243468
D13: Median | H13: =MEDIAN(H4:H10) -> 0.02413044 | I13: =MEDIAN(I4:I10) -> 0.023561881 | J13: =MEDIAN(J4:J10) -> 0.3 | K13: =MEDIAN(K4:K10) -> 0.59 | L13: =MEDIAN(L4:L10) -> 0.58998852
D15: Alkem Lab | E15: ALKEM | F15: 62167.79 | G15: 2047.16
C17: WACC
C18: Industry Mix
D19: Proportion of Debt | E19: =I12 -> 0.041362951
D20: Proportion of Equity | E20: =1-E19 -> 0.95863705
C22: Company Mix
D23: Market Cap | E23: =F15 -> 62167.79
D24: Total Debt | E24: =G15 -> 2047.16
D25: Debt / Equity | E25: =E24/E23 -> 0.032929593
C27: Cost of Debt
D28: Pre-Tax Cost of Debt | E28: =Debt!M9 -> 0.09
D29: Tax Rate | E29: ='Income Statement'!M31 -> 0.31
D30: After-Tax Cost of Debt | E30: =E28*(1-E29) -> 0.0621
C32: Cost of Equity
D33: Risk Free Rate | E33: 0.069
D34: Equity Market Return | E34: ='Index Price'!H5 -> 0.083998188
D35: Equity Risk Premium | E35: =E34-E33 -> 0.014998188
D36: Levered Equity Beta | E36: =L13*(1+E25)*(1-E29) -> 0.42049746
D37: Cost of Equity | E37: =E33+E36*E35 -> 0.0753067
D39: WACC | E39: =(E19*E30)+(E20*E37) -> 0.074760432

Sheet Index Price
A1: Sensex Index Data
D2: Date | E2: Price
D3: 46266 | E3: 74781.76
D4: 46235 | E4: 76957.27 | G4: Period in years | H4: =YEARFRAC(D143,D3) -> 11.666667
D5: 46204 | E5: 78094.64 | G5: Return % | H5: =_xlfn.RRI(H4,E143,E3) -> 0.083998188
D6: 46174 | E6: 76478.67
D7: 46143 | E7: 74775.74
D8: 46113 | E8: 76913.5
