Workbook

Sheet Index
A1: TATA Consultncy Services Ltd | G1: Color Codes
B2: Core Financial Statements | G2: Blue | H2: Inputs & forecast Assumptions
C3: Income Statement | G3: Black | H3: fomulas, reference cell on same sheet
C4: Balance Sheet | G4: Green | H4: linked cells from other sheets
C5: Cash Flows | G5: Red | H5: Link from other sources
B6: Supporting Schedules
C7: Ratio Analysis
C8: Revenue Built Up
C9: Cost Sheet
C10: Working Cap
C11: Dep & Capex
B12: Valuations
C13: DCF
C14: Relative Valuation

Sheet Income Statement
B1: TATA Consultancy Services Ltd | C1: Historicals | H1: Forecasts
B2: (All data in ₹ Crore, except per share Information) | C2: FY 2022 | D2: FY2023 | E2: FY 2024 | F2: FY 2025 | G2: FY 2026 | H2: FY 2027 | I2: FY 2028 | J2: FY 2029 | K2: FY 2030 | L2: FY 2031
B3: Revenue | C3: 191754 | D3: 225458 | E3: 240893 | F3: 255324 | G3: 267021 | H3: ='Revenue Built Up'!H10 -> 283443.21 | I3: ='Revenue Built Up'!I10 -> 299071.01 | J3: ='Revenue Built Up'!J10 -> 313882.45 | K3: ='Revenue Built Up'!K10 -> 327053.58 | L3: ='Revenue Built Up'!L10 -> 340912.2
B4: Employee Expenses | C4: -107554 | D4: -127522 | E4: -140131 | F4: -145788 | G4: -154994 | H4: =-'Cost Sheet'!H5 -> -164293.64 | I4: =-'Cost Sheet'!I5 -> -174151.26 | J4: =-'Cost Sheet'!J5 -> -184600.33 | K4: =-'Cost Sheet'!K5 -> -195676.35 | L4: =-'Cost Sheet'!L5 -> -207416.94
B5: Cost of equipment & software licences | C5: -1163 | D5: -1881 | E5: -3702 | F5: -11648 | G5: -4399 | H5: =-'Cost Sheet'!H9 -> -4486.98 | I5: =-'Cost Sheet'!I9 -> -4576.7196 | J5: =-'Cost Sheet'!J9 -> -4668.254 | K5: =-'Cost Sheet'!K9 -> -4761.6191 | L5: =-'Cost Sheet'!L9 -> -4856.8515
B6: Cost of Services | C6: =SUM(C4:C5) -> -108717 | D6: =SUM(D4:D5) -> -129403 | E6: =SUM(E4:E5) -> -143833 | F6: =SUM(F4:F5) -> -157436 | G6: =SUM(G4:G5) -> -159393 | H6: =SUM(H4:H5) -> -168780.62 | I6: =SUM(I4:I5) -> -178727.98 | J6: =SUM(J4:J5) -> -189268.59 | ... L6: =SUM(L4:L5) -> -212273.79
B7: Gross Profit | C7: =SUM(C3,C6) -> 83037 | D7: =SUM(D3,D6) -> 96055 | E7: =SUM(E3,E6) -> 97060 | F7: =SUM(F3,F6) -> 97888 | G7: =SUM(G3,G6) -> 107628 | H7: =SUM(H3,H6) -> 114662.58 | I7: =SUM(I3,I6) -> 120343.03 | J7: =SUM(J3,J6) -> 124613.86 | ... L7: =SUM(L3,L6) -> 128638.41
B8: Other Expenses | C8: -29980 | D8: -36796 | E8: -32764 | F8: -30481 | G8: -35230 | H8: =-'Cost Sheet'!H13 -> -39986.05 | I8: =-'Cost Sheet'!I13 -> -45384.167 | J8: =-'Cost Sheet'!J13 -> -51511.029 | K8: =-'Cost Sheet'!K13 -> -58465.018 | L8: =-'Cost Sheet'!L13 -> -66357.796
B9: EBITDA | C9: =SUM(C7:C8) -> 53057 | D9: =SUM(D7:D8) -> 59259 | E9: =SUM(E7:E8) -> 64296 | F9: =SUM(F7:F8) -> 67407 | G9: =SUM(G7:G8) -> 72398 | H9: =SUM(H7:H8) -> 74676.535 | I9: =SUM(I7:I8) -> 74958.862 | J9: =SUM(J7:J8) -> 73102.835 | ... L9: =SUM(L7:L8) -> 62280.617
B10: Depreciation | C10: -4604 | D10: -5022 | E10: -4985 | F10: -5242 | G10: -5560 | H10: ='Dep & Capex'!H9 -> -6262.6694 | I10: ='Dep & Capex'!I9 -> -7218.6996 | J10: ='Dep & Capex'!J9 -> -8224.576 | K10: ='Dep & Capex'!K9 -> -9410.1683 | L10: ='Dep & Capex'!L9 -> -11425.691
B11: EBIT | C11: =SUM(C9:C10) -> 48453 | D11: =SUM(D9:D10) -> 54237 | E11: =SUM(E9:E10) -> 59311 | F11: =SUM(F9:F10) -> 62165 | G11: =SUM(G9:G10) -> 66838 | H11: =SUM(H9:H10) -> 68413.866 | I11: =SUM(I9:I10) -> 67740.163 | J11: =SUM(J9:J10) -> 64878.259 | ... L11: =SUM(L9:L10) -> 50854.927
B12: Add; Other Income | C12: 4018 | D12: 3449 | E12: 4422 | F12: 3962 | G12: 4402 | H12: =G12 -> 4402 | I12: =H12 -> 4402 | J12: =I12 -> 4402 | K12: =J12 -> 4402 | L12: =K12 -> 4402
B13: Less; Interest Charges | C13: -784 | D13: -779 | E13: -778 | F13: -796 | G13: -1227 | H13: =G13 -> -1227 | I13: =H13 -> -1227 | J13: =I13 -> -1227 | K13: =J13 -> -1227 | L13: =K13 -> -1227
B14: Earning before tax and Exceptional itms | C14: =SUM(C11:C13) -> 51687 | D14: =SUM(D11:D13) -> 56907 | E14: =SUM(E11:E13) -> 62955 | F14: =SUM(F11:F13) -> 65331 | G14: =SUM(G11:G13) -> 70013 | H14: =SUM(H11:H13) -> 71588.866 | I14: =SUM(I11:I13) -> 70915.163 | J14: =SUM(J11:J13) -> 68053.259 | ... L14: =SUM(L11:L13) -> 54029.927
B15: Less; Exceptional Items
B16: Re-structuring expenses | C16: 0 | D16: 0 | E16: 0 | F16: 0 | G16: -1388 | H16: 0 | I16: 0 | J16: 0 | K16: 0 | L16: 0
B17: Statutory impact of new Labour Codes | C17: 0 | D17: 0 | E17: 0 | F17: 0 | G17: -2128 | H17: 0 | I17: 0 | J17: 0 | K17: 0 | L17: 0
B18: Provision towards legal claim | C18: 0 | D18: 0 | E18: -958 | F18: 0 | G18: -1010 | H18: 0 | I18: 0 | J18: 0 | K18: 0 | L18: 0
B19: EBT | C19: =SUM(C14:C18) -> 51687 | D19: =SUM(D14:D18) -> 56907 | E19: =SUM(E14:E18) -> 61997 | F19: =SUM(F14:F18) -> 65331 | G19: =SUM(G14:G18) -> 65487 | H19: =SUM(H14:H18) -> 71588.866 | I19: =SUM(I14:I18) -> 70915.163 | J19: =SUM(J14:J18) -> 68053.259 | ... L19: =SUM(L14:L18) -> 54029.927
B20: Less; Tax Expenses
B21: Current tax | C21: -13654 | D21: -14757 | E21: -15864 | F21: -16910 | G21: -16388 | H21: =-H19*H32 -> -17526.903 | I21: =-I19*I32 -> -17361.962 | J21: =-J19*J32 -> -16661.29 | K21: =-K19*K32 -> -15158.58 | L21: =-L19*L32 -> -13227.997
B22: Deferred tax | C22: 416 | D22: 153 | E22: -34 | F22: 376 | G22: 355 | H22: =G22 -> 355 | I22: =H22 -> 355 | J22: =I22 -> 355 | K22: =J22 -> 355 | L22: =K22 -> 355
B23: Net Profit | C23: =SUM(C19:C22) -> 38449 | D23: =SUM(D19:D22) -> 42303 | E23: =SUM(E19:E22) -> 46099 | F23: =SUM(F19:F22) -> 48797 | G23: =SUM(G19:G22) -> 49454 | H23: =SUM(H19:H22) -> 54416.963 | I23: =SUM(I19:I22) -> 53908.201 | J23: =SUM(J19:J22) -> 51746.969 | ... L23: =SUM(L19:L22) -> 41156.93
B24: Other Comprehensive Income/Loss | C24: -95 | D24: 492 | E24: 237 | F24: 589 | G24: 2750 | H24: =G24 -> 2750 | I24: =H24 -> 2750 | J24: =I24 -> 2750 | K24: =J24 -> 2750 | L24: =K24 -> 2750
B25: Total profit for the year | C25: =SUM(C23:C24) -> 38354 | D25: =SUM(D23:D24) -> 42795 | E25: =SUM(E23:E24) -> 46336 | F25: =SUM(F23:F24) -> 49386 | G25: =SUM(G23:G24) -> 52204 | H25: =SUM(H23:H24) -> 57166.963 | I25: =SUM(I23:I24) -> 56658.201 | J25: =SUM(J23:J24) -> 54496.969 | ... L25: =SUM(L23:L24) -> 43906.93
B26: Per Share Data
B27: Total Dividend Paid | C27: =-'Cash Flows '!C61 -> 13317 | D27: =-'Cash Flows '!D61 -> 41347 | E27: =-'Cash Flows '!E61 -> 25137 | F27: =-'Cash Flows '!F61 -> 44864 | G27: =-'Cash Flows '!G61 -> 39437 | H27: =H30*H28 -> 43394.705 | I27: =I30*I28 -> 42988.994 | J27: =J30*J28 -> 41265.524 | K27: =K30*K28 -> 37569.249 | L27: =L30*L28 -> 32820.517
B28: Weighted average number of equity shares | C28: 369.8 | D28: 365.9 | E28: 364.6 | F28: 361.8 | G28: 361.8 | H28: =G28 -> 361.8 | I28: =H28 -> 361.8 | J28: =I28 -> 361.8 | K28: =J28 -> 361.8 | L28: =K28 -> 361.8
B29: Earning Per Share (Basic & Diluted) ₹ | C29: 103.62 | D29: 115.19 | E29: 125.8 | F29: 134.19 | G29: 136.01 | H29: =H23/H28 -> 150.4062 | I29: =I23/I28 -> 149 | J29: =J23/J28 -> 143.02645 | K29: =K23/K28 -> 130.21515 | L29: =L23/L28 -> 113.75603
B30: Dividend Per Share (₹) | C30: =C27/C28 -> 36.011357 | D30: =D27/D28 -> 113.00082 | E30: =E27/E28 -> 68.944048 | F30: =F27/F28 -> 124.00221 | G30: =G27/G28 -> 109.00221 | H30: =H29*G31 -> 119.94114 | I30: =I29*H31 -> 118.81977 | J30: =J29*I31 -> 114.05617 | K30: =K29*J31 -> 103.83983 | L30: =L29*K31 -> 90.71453
B31: Dividend Pay Out Ratio | C31: =C27/C23 -> 0.34635491 | D31: =D27/D23 -> 0.97740113 | E31: =E27/E23 -> 0.54528298 | F31: =F27/F23 -> 0.91940078 | G31: =G27/G23 -> 0.79744813 | H31: =H27/H23 -> 0.79744813 | I31: =I27/I23 -> 0.79744813 | J31: =J27/J23 -> 0.79744813 | ... L31: =L27/L23 -> 0.79744813
B32: Tax Rate | C32: =-SUM(C21:C22)/C19 -> 0.25611856 | D32: =-SUM(D21:D22)/D19 -> 0.25662924 | E32: =-SUM(E21:E22)/E19 -> 0.25643176 | F32: =-SUM(F21:F22)/F19 -> 0.25308047 | G32: =-SUM(G21:G22)/G19 -> 0.24482722 | H32: =G32 -> 0.24482722 | I32: =H32 -> 0.24482722 | J32: =I32 -> 0.24482722 | K32: =J32 -> 0.24482722 | L32: =K32 -> 0.24482722

Sheet Balance Sheet
B1: TATA Consultancy Services Ltd | C1: Historicals | H1: Forecasts
B2: (All data in ₹ Crore, except per share Information) | C2: FY 2022 | D2: FY2023 | E2: FY 2024 | F2: FY 2025 | G2: FY 2026 | H2: FY 2027 | I2: FY 2028 | J2: FY 2029 | K2: FY 2030 | L2: FY 2031
B3: Current Assets
B4: Cash & Cash Equivalents | C4: 12488 | D4: 7123 | E4: 9016 | F4: 8342 | G4: 6417 | H4: ='Cash Flows '!H76 -> 21090.708 | I4: ='Cash Flows '!I76 -> 33148.181 | J4: ='Cash Flows '!J76 -> 45714.786 | K4: ='Cash Flows '!K76 -> 57061.387 | L4: ='Cash Flows '!L76 -> 68763.716
B5: Other Bank Balances | C5: 5733 | D5: 3909 | E5: 4270 | F5: 7121 | G5: 6491 | H5: =G5 -> 6491 | I5: =H5 -> 6491 | J5: =I5 -> 6491 | K5: =J5 -> 6491 | L5: =K5 -> 6491
B6: Receivables | C6: 41810 | D6: 49954 | E6: 53577 | F6: 59046 | G6: 67714 | H6: ='Working Cap'!H6 -> 66007.322 | I6: ='Working Cap'!I6 -> 69646.673 | J6: ='Working Cap'!J6 -> 73095.914 | K6: ='Working Cap'!K6 -> 76163.162 | L6: ='Working Cap'!L6 -> 79390.512
B7: Investments | C7: 30262 | D7: 36897 | E7: 31481 | F7: 30689 | G7: 33770 | H7: =G7 -> 33770 | I7: =H7 -> 33770 | J7: =I7 -> 33770 | K7: =J7 -> 33770 | L7: =K7 -> 33770
B8: Loans | C8: 6445 | D8: 1325 | E8: 491 | F8: 9 | G8: 1659 | H8: =G8 -> 1659 | I8: =H8 -> 1659 | J8: =I8 -> 1659 | K8: =J8 -> 1659 | L8: =K8 -> 1659
B9: Other Financial Assets | C9: 1390 | D9: 1319 | E9: 1703 | F9: 2742 | G9: 1833 | H9: =G9 -> 1833 | I9: =H9 -> 1833 | J9: =I9 -> 1833 | K9: =J9 -> 1833 | L9: =K9 -> 1833
B10: Income tax Assets | C10: 11 | D10: 8 | E10: 151 | F10: 257 | G10: 1259 | H10: =G10 -> 1259 | I10: =H10 -> 1259 | J10: =I10 -> 1259 | K10: =J10 -> 1259 | L10: =K10 -> 1259
B11: Other Assets | C11: 10151 | D11: 9707 | E11: 12267 | F11: 14784 | G11: 16533 | H11: =G11 -> 16533 | I11: =H11 -> 16533 | J11: =I11 -> 16533 | K11: =J11 -> 16533 | L11: =K11 -> 16533
B12: Inventories | C12: 20 | D12: 28 | E12: 28 | F12: 21 | G12: 29 | H12: 30 | I12: =H12 -> 30 | J12: =I12 -> 30 | K12: =J12 -> 30 | L12: =K12 -> 30
A13: 1 | B13: Total Current Assets | C13: =SUM(C4:C12) -> 108310 | D13: =SUM(D4:D12) -> 110270 | E13: =SUM(E4:E12) -> 112984 | F13: =SUM(F4:F12) -> 123011 | G13: =SUM(G4:G12) -> 135705 | H13: =SUM(H4:H12) -> 148673.03 | I13: =SUM(I4:I12) -> 164369.85 | J13: =SUM(J4:J12) -> 180385.7 | ... L13: =SUM(L4:L12) -> 209729.23
B14: Non Current Assets
B15: Property, plant and equipment | C15: 10774 | D15: 10230 | E15: 9376 | F15: 10978 | G15: 11032 | H15: ='Dep & Capex'!H11 -> 10438.195 | I15: ='Dep & Capex'!I11 -> 9200.9153 | J15: ='Dep & Capex'!J11 -> 7253.9884 | K15: ='Dep & Capex'!K11 -> 6020.1595 | L15: ='Dep & Capex'!L11 -> 3117.2739
B16: Capital work-in-progress | C16: 1205 | D16: 1234 | E16: 1564 | F16: 1546 | G16: 2665 | H16: =G16 -> 2665 | I16: =H16 -> 2665 | J16: =I16 -> 2665 | K16: =J16 -> 2665 | L16: =K16 -> 2665
B17: Right-of-use assets | C17: 7636 | D17: 7560 | E17: 7886 | F17: 9275 | G17: 11027 | H17: =G17 -> 11027 | I17: =H17 -> 11027 | J17: =I17 -> 11027 | K17: =J17 -> 11027 | L17: =K17 -> 11027
B18: Goodwill | C18: 1787 | D18: 1858 | E18: 1832 | F18: 1860 | G18: 9108 | H18: =G18 -> 9108 | I18: =H18 -> 9108 | J18: =I18 -> 9108 | K18: =J18 -> 9108 | L18: =K18 -> 9108
B19: Other intangible assets | C19: 1101 | D19: 867 | E19: 510 | F19: 940 | G19: 176 | H19: =G19 -> 176 | I19: =H19 -> 176 | J19: =I19 -> 176 | K19: =J19 -> 176 | L19: =K19 -> 176
B20: Investments | C20: 223 | D20: 266 | E20: 281 | F20: 275 | G20: 218 | H20: =G20 -> 218 | I20: =H20 -> 218 | J20: =I20 -> 218 | K20: =J20 -> 218 | L20: =K20 -> 218
B21: Trade receivables | C21: 200 | D21: 348 | E21: 143 | F21: 129 | G21: 213 | H21: =G21 -> 213 | I21: =H21 -> 213 | J21: =I21 -> 213 | K21: =J21 -> 213 | L21: =K21 -> 213
B22: Loans | C22: 311 | D22: 173 | E22: 2 | F22: 25 | G22: 775 | H22: =G22 -> 775 | I22: =H22 -> 775 | J22: =I22 -> 775 | K22: =J22 -> 775 | L22: =K22 -> 775
B23: Other financial assets | C23: 2253 | D23: 2149 | E23: 3272 | F23: 2731 | G23: 2944 | H23: =G23 -> 2944 | I23: =H23 -> 2944 | J23: =I23 -> 2944 | K23: =J23 -> 2944 | L23: =K23 -> 2944
B24: Deferred tax assets | C24: 3708 | D24: 3307 | E24: 3403 | F24: 3578 | G24: 4465 | H24: =G24 -> 4465 | I24: =H24 -> 4465 | J24: =I24 -> 4465 | K24: =J24 -> 4465 | L24: =K24 -> 4465
B25: Income tax assets | C25: 1983 | D25: 2583 | E25: 1600 | F25: 1569 | G25: 1439 | H25: =G25 -> 1439 | I25: =H25 -> 1439 | J25: =I25 -> 1439 | K25: =J25 -> 1439 | L25: =K25 -> 1439
B26: Other assets | C26: 2023 | D26: 2806 | E26: 3596 | F26: 3712 | G26: 2605 | H26: =G26 -> 2605 | I26: =H26 -> 2605 | J26: =I26 -> 2605 | K26: =J26 -> 2605 | L26: =K26 -> 2605
B27: Total Non Current Assets | C27: =SUM(C15:C26) -> 33204 | D27: =SUM(D15:D26) -> 33381 | E27: =SUM(E15:E26) -> 33465 | F27: =SUM(F15:F26) -> 36618 | G27: =SUM(G15:G26) -> 46667 | H27: =SUM(H15:H26) -> 46073.195 | I27: =SUM(I15:I26) -> 44835.915 | J27: =SUM(J15:J26) -> 42888.988 | ... L27: =SUM(L15:L26) -> 38752.274
A28: 2 | B28: Total Assets | C28: =C13+C27 -> 141514 | D28: =D13+D27 -> 143651 | E28: =E13+E27 -> 146449 | F28: =F13+F27 -> 159629 | G28: =G13+G27 -> 182372 | H28: =H13+H27 -> 194746.22 | I28: =I13+I27 -> 209205.77 | J28: =J13+J27 -> 223274.69 | ... L28: =L13+L27 -> 248481.5
B29: Current Liabilities
B30: Lease liabilities | C30: 1450 | D30: 1485 | E30: 1505 | F30: 1554 | G30: 1830 | H30: =G30 -> 1830 | I30: =H30 -> 1830 | J30: =I30 -> 1830 | K30: =J30 -> 1830 | L30: =K30 -> 1830
B31: Trade payables | C31: 8045 | D31: 10515 | E31: 9981 | F31: 13909 | G31: 14808 | H31: ='Working Cap'!H7 -> 13409.967 | I31: ='Working Cap'!I7 -> 14200.305 | J31: ='Working Cap'!J7 -> 15037.778 | K31: ='Working Cap'!K7 -> 15925.209 | L31: ='Working Cap'!L7 -> 16865.589
B32: Other financial liabilities | C32: 7687 | D32: 9068 | E32: 8362 | F32: 8542 | G32: 11194 | H32: =G32 -> 11194 | I32: =H32 -> 11194 | J32: =I32 -> 11194 | K32: =J32 -> 11194 | L32: =K32 -> 11194
B33: Unearned and deferred revenue | C33: 3635 | D33: 3843 | E33: 3640 | F33: 4028 | G33: 4487 | H33: =G33 -> 4487 | I33: =H33 -> 4487 | J33: =I33 -> 4487 | K33: =J33 -> 4487 | L33: =K33 -> 4487
B34: Other liabilities | C34: 8392 | D34: 4892 | E34: 6524 | F34: 7188 | G34: 6866 | H34: =G34 -> 6866 | I34: =H34 -> 6866 | J34: =I34 -> 6866 | K34: =J34 -> 6866 | L34: =K34 -> 6866
B35: Provisions | C35: 1411 | D35: 345 | E35: 140 | F35: 180 | G35: 1378 | H35: =G35 -> 1378 | I35: =H35 -> 1378 | J35: =I35 -> 1378 | K35: =J35 -> 1378 | L35: =K35 -> 1378
B36: Employee benefit obligations | C36: 3810 | D36: 4065 | E36: 4519 | F36: 4885 | G36: 5600 | H36: =G36 -> 5600 | I36: =H36 -> 5600 | J36: =I36 -> 5600 | K36: =J36 -> 5600 | L36: =K36 -> 5600
B37: Income tax liabilities | C37: 7921 | D37: 9345 | E37: 11433 | F37: 12715 | G37: 14751 | H37: =G37 -> 14751 | I37: =H37 -> 14751 | J37: =I37 -> 14751 | K37: =J37 -> 14751 | L37: =K37 -> 14751
A38: 3 | B38: Total Current Liabilities | C38: =SUM(C30:C37) -> 42351 | D38: =SUM(D30:D37) -> 43558 | E38: =SUM(E30:E37) -> 46104 | F38: =SUM(F30:F37) -> 53001 | G38: =SUM(G30:G37) -> 60914 | H38: =SUM(H30:H37) -> 59515.967 | I38: =SUM(I30:I37) -> 60306.305 | J38: =SUM(J30:J37) -> 61143.778 | ... L38: =SUM(L30:L37) -> 62971.589
B39: Non Current Liabilities
B40: Class B compulsorily convertible preference shares | C40: 0 | D40: 0 | E40: 0 | F40: 0 | G40: 126 | H40: =G40 -> 126 | I40: =H40 -> 126 | J40: =I40 -> 126 | K40: =J40 -> 126 | L40: =K40 -> 126
...

Sheet Cash Flows 
B1: TATA Consultancy Services Ltd | C1: Historicals | H1: Forecasts
B2: (All data in ₹ Crore, except per share Information) | C2: FY 2022 | D2: FY2023 | E2: FY 2024 | F2: FY 2025 | G2: FY 2026 | H2: FY 2027 | I2: FY 2028 | J2: FY 2029 | K2: FY 2030 | L2: FY 2031
B3: Cash Flow from Operating Activities
B4: Net Income | C4: 38449 | D4: 42303 | E4: 46099 | F4: 48797 | G4: 49454 | H4: ='Income Statement'!H25 -> 57166.963 | I4: ='Income Statement'!I25 -> 56658.201 | J4: ='Income Statement'!J25 -> 54496.969 | K4: ='Income Statement'!K25 -> 49861.84 | L4: ='Income Statement'!L25 -> 43906.93
B5: Adjustments for;
B6: Depreciation and amortisation expense | C6: 4604 | D6: 5022 | E6: 4985 | F6: 5242 | G6: 5560 | H6: =-'Dep & Capex'!H9 -> 6262.6694 | I6: =-'Dep & Capex'!I9 -> 7218.6996 | J6: =-'Dep & Capex'!J9 -> 8224.576 | K6: =-'Dep & Capex'!K9 -> 9410.1683 | L6: =-'Dep & Capex'!L9 -> 11425.691
B7: Bad debts, advances written off | C7: 135 | D7: 140 | E7: 114 | F7: 128 | G7: 184 | H7: 0 | I7: =H7 -> 0 | J7: =I7 -> 0 | K7: =J7 -> 0 | L7: =K7 -> 0
B8: Provision towards legal claim | C8: 0 | D8: 0 | E8: 0 | F8: 0 | G8: 1010 | H8: 0 | I8: =H8 -> 0 | J8: =I8 -> 0 | K8: =J8 -> 0 | L8: =K8 -> 0
B9: Provision towards Re-structuring expenses | C9: 0 | D9: 0 | E9: 0 | F9: 0 | G9: 120 | H9: 0 | I9: =H9 -> 0 | J9: =I9 -> 0 | K9: =J9 -> 0 | L9: =K9 -> 0
B10: Tax expense | C10: 13238 | D10: 14604 | E10: 15898 | F10: 16534 | G10: 16033 | H10: =-SUM('Income Statement'!H21:H22) -> 17171.903 | I10: =-SUM('Income Statement'!I21:I22) -> 17006.962 | J10: =-SUM('Income Statement'!J21:J22) -> 16306.29 | K10: =-SUM('Income Statement'!K21:K22) -> 14803.58 | L10: =-SUM('Income Statement'!L21:L22) -> 12872.997
B11: Net gain on lease modification | C11: -7 | D11: 2 | E11: -7 | F11: -15 | G11: -110 | H11: 0 | I11: =H11 -> 0 | J11: =I11 -> 0 | K11: =J11 -> 0 | L11: =K11 -> 0
B12: Net gain on sub-lease | C12: 9 | D12: 0 | E12: 0 | F12: 0 | G12: -8 | H12: 0 | I12: 0 | J12: 0 | K12: 0 | L12: 0
B13: Unrealised foreign exchange gain | C13: -120 | D13: -189 | E13: -17 | F13: -1 | G13: -176 | H13: 0 | I13: =H13 -> 0 | J13: =I13 -> 0 | K13: =J13 -> 0 | L13: =K13 -> 0
B14: Net gain on disposal of property, plant and equipment | C14: -23 | D14: -26 | E14: -7 | F14: -20 | G14: -17 | H14: 0 | I14: 0 | J14: 0 | K14: 0 | L14: 0
B15: Net gain on disposal / fair valuation of investments | C15: -198 | D15: -224 | E15: -312 | F15: -269 | G15: -701 | H15: 0 | I15: =H15 -> 0 | J15: =I15 -> 0 | K15: =J15 -> 0 | L15: =K15 -> 0
B16: Net gain on fair valuation of call option | C16: 0 | D16: 0 | E16: 0 | F16: 0 | G16: -17 | H16: 0 | I16: 0 | J16: 0 | K16: 0 | L16: 0
B17: Transaction cost on incorporation of subsidiary | C17: 0 | D17: 0 | E17: 0 | F17: 0 | G17: 18 | H17: 0 | I17: 0 | J17: 0 | K17: 0 | L17: 0
B18: Interest income | C18: -2663 | D18: -3248 | E18: -3781 | F18: -3296 | G18: -3854 | H18: 0 | I18: =H18 -> 0 | J18: =I18 -> 0 | K18: =J18 -> 0 | L18: =K18 -> 0
B19: Dividend income | C19: -4 | D19: -15 | E19: -41 | F19: -43 | G19: -35 | H19: 0 | I19: =H19 -> 0 | J19: =I19 -> 0 | K19: =J19 -> 0 | L19: =K19 -> 0
B20: Finance costs | C20: 784 | D20: 779 | E20: 778 | F20: 796 | G20: 1227 | H20: 0 | I20: 0 | J20: 0 | K20: 0 | L20: 0
B21: Total | C21: =SUM(C4:C20) -> 54204 | D21: =SUM(D4:D20) -> 59148 | E21: =SUM(E4:E20) -> 63709 | F21: =SUM(F4:F20) -> 67853 | G21: =SUM(G4:G20) -> 68688 | H21: =SUM(H4:H20) -> 80601.535 | I21: =SUM(I4:I20) -> 80883.862 | J21: =SUM(J4:J20) -> 79027.835 | ... L21: =SUM(L4:L20) -> 68205.617
B22: Change in Working Capital
B23: Inventories | C23: -12 | D23: -8 | E23: 0 | F23: 7 | G23: -8 | H23: ='Balance Sheet'!G12-'Balance Sheet'!H12 -> -1 | I23: ='Balance Sheet'!H12-'Balance Sheet'!I12 -> 0 | J23: ='Balance Sheet'!I12-'Balance Sheet'!J12 -> 0 | K23: ='Balance Sheet'!J12-'Balance Sheet'!K12 -> 0 | L23: ='Balance Sheet'!K12-'Balance Sheet'!L12 -> 0
B24: Trade receivables | C24: -5144 | D24: -7683 | E24: -3332 | F24: -5228 | G24: -5248 | H24: ='Working Cap'!G6-'Working Cap'!H6 -> 1706.6783 | I24: ='Working Cap'!H6-'Working Cap'!I6 -> -3639.3511 | J24: ='Working Cap'!I6-'Working Cap'!J6 -> -3449.2407 | K24: ='Working Cap'!J6-'Working Cap'!K6 -> -3067.249 | L24: ='Working Cap'!K6-'Working Cap'!L6 -> -3227.3498
B25: Loan & Other Financial Assets | C25: -116 | D25: 261 | E25: -301 | F25: -738 | G25: 197 | H25: 0 | I25: =H25 -> 0 | J25: =I25 -> 0 | K25: =J25 -> 0 | L25: =K25 -> 0
B26: Other Assets | C26: 807 | D26: -25 | E26: -3160 | F26: -2552 | G26: 837 | H26: 0 | I26: =H26 -> 0 | J26: =I26 -> 0 | K26: =J26 -> 0 | L26: =K26 -> 0
B27: Trade Payables | C27: 186 | D27: 2036 | E27: -632 | F27: 3718 | G27: -1105 | H27: ='Working Cap'!H7-'Working Cap'!G7 -> -1398.0329 | I27: ='Working Cap'!I7-'Working Cap'!H7 -> 790.33803 | J27: ='Working Cap'!J7-'Working Cap'!I7 -> 837.47312 | K27: ='Working Cap'!K7-'Working Cap'!J7 -> 887.4306 | L27: ='Working Cap'!L7-'Working Cap'!K7 -> 940.37971
B28: Unearned & Deffered revenue | C28: -103 | D28: 39 | E28: -740 | F28: 395 | G28: 320 | H28: 0 | I28: =H28 -> 0 | J28: =I28 -> 0 | K28: =J28 -> 0 | L28: =K28 -> 0
B29: Other Financial Liabilities | C29: 1153 | D29: 1417 | E29: -695 | F29: -119 | G29: 2814 | H29: 0 | I29: =H29 -> 0 | J29: =I29 -> 0 | K29: =J29 -> 0 | L29: =K29 -> 0
B30: Other Liabilities & Provisions | C30: 460 | D30: -254 | E30: 1978 | F30: 1158 | G30: -17 | H30: 0 | I30: =H30 -> 0 | J30: =I30 -> 0 | K30: =J30 -> 0 | L30: =K30 -> 0
B31: Taxes Paid | C31: -11486 | D31: -12966 | E31: -12489 | F31: -15586 | G31: -14384 | H31: =SUM('Income Statement'!H21:H22) -> -17171.903 | I31: =SUM('Income Statement'!I21:I22) -> -17006.962 | J31: =SUM('Income Statement'!J21:J22) -> -16306.29 | K31: =SUM('Income Statement'!K21:K22) -> -14803.58 | L31: =SUM('Income Statement'!L21:L22) -> -12872.997
B32: Total Changes In working Capital | C32: =SUM(C23:C31) -> -14255 | D32: =SUM(D23:D31) -> -17183 | E32: =SUM(E23:E31) -> -19371 | F32: =SUM(F23:F31) -> -18945 | G32: =SUM(G23:G31) -> -16594 | H32: =SUM(H23:H31) -> -16864.257 | I32: =SUM(I23:I31) -> -19855.975 | J32: =SUM(J23:J31) -> -18918.058 | ... L32: =SUM(L23:L31) -> -15159.967
B33: Total Cash generated from operating Activities | C33: =SUM(C32,C21) -> 39949 | D33: =SUM(D32,D21) -> 41965 | E33: =SUM(E32,E21) -> 44338 | F33: =SUM(F32,F21) -> 48908 | G33: =SUM(G32,G21) -> 52094 | H33: =SUM(H32,H21) -> 63737.278 | I33: =SUM(I32,I21) -> 61027.887 | J33: =SUM(J32,J21) -> 60109.777 | ... L33: =SUM(L32,L21) -> 53045.651
B34: Cash flow from Investing Activities
B35: Bank deposits placed | C35: -15947 | D35: -4548 | E35: -9471 | F35: -10496 | G35: -8506 | H35: 0 | I35: =H35 -> 0 | J35: =I35 -> 0 | K35: =J35 -> 0 | L35: =K35 -> 0
B36: Inter-corporate deposits placed | C36: -14619 | D36: -8293 | E36: 0 | F36: 0 | G36: -1500 | H36: 0 | I36: =H36 -> 0 | J36: =I36 -> 0 | K36: =J36 -> 0 | L36: =K36 -> 0
B37: Purchase of investments | C37: -75374 | D37: -129745 | E37: -141011 | F37: -145962 | G37: -151864 | H37: 0 | I37: =H37 -> 0 | J37: =I37 -> 0 | K37: =J37 -> 0 | L37: =K37 -> 0
B38: Payment for purchase of property, plant and equipment | C38: -2483 | D38: -2532 | E38: -2202 | F38: -2917 | G38: -3670 | H38: =-'Dep & Capex'!H4 -> -5668.8641 | I38: =-'Dep & Capex'!I4 -> -5981.4201 | J38: =-'Dep & Capex'!J4 -> -6277.649 | K38: =-'Dep & Capex'!K4 -> -8176.3395 | L38: =-'Dep & Capex'!L4 -> -8522.805
B39: Payment including advances for acquiring right-of-use assets | C39: -15 | D39: -213 | E39: -30 | F39: -76 | G39: -109 | H39: 0 | I39: =H39 -> 0 | J39: =I39 -> 0 | K39: =J39 -> 0 | L39: =K39 -> 0
B40: Payment for purchase of intangible assets | C40: -497 | D40: -355 | E40: -442 | F40: -944 | G40: -367 | H40: 0 | I40: =H40 -> 0 | J40: =I40 -> 0 | K40: =J40 -> 0 | L40: =K40 -> 0
...

Sheet Ratio Analysis
B1: TATA Consultancy Services Ltd | C1: Historicals | H1: Forecasts
B2: (All data in ₹ Crore, except per share Information) | C2: FY 2022 | D2: FY2023 | E2: FY 2024 | F2: FY 2025 | G2: FY 2026 | H2: FY 2027 | I2: FY 2028 | J2: FY 2029 | K2: FY 2030 | L2: FY 2031
B3: Liquidity Ratios
B4: Current Ratio | C4: ='Balance Sheet'!C13/'Balance Sheet'!C38 -> 2.5574367 | D4: ='Balance Sheet'!D13/'Balance Sheet'!D38 -> 2.5315671 | E4: ='Balance Sheet'!E13/'Balance Sheet'!E38 -> 2.4506334 | F4: ='Balance Sheet'!F13/'Balance Sheet'!F38 -> 2.3209185 | G4: ='Balance Sheet'!G13/'Balance Sheet'!G38 -> 2.227813 | H4: ='Balance Sheet'!H13/'Balance Sheet'!H38 -> 2.498036 | I4: ='Balance Sheet'!I13/'Balance Sheet'!I38 -> 2.7255832 | J4: ='Balance Sheet'!J13/'Balance Sheet'!J38 -> 2.950189 | ... L4: ='Balance Sheet'!L13/'Balance Sheet'!L38 -> 3.3305374
B5: Quick Ratio | C5: =SUM('Balance Sheet'!C4:C11)/'Balance Sheet'!C38 -> 2.5569644 | D5: =SUM('Balance Sheet'!D4:D11)/'Balance Sheet'!D38 -> 2.5309243 | E5: =SUM('Balance Sheet'!E4:E11)/'Balance Sheet'!E38 -> 2.450026 | F5: =SUM('Balance Sheet'!F4:F11)/'Balance Sheet'!F38 -> 2.3205223 | G5: =SUM('Balance Sheet'!G4:G11)/'Balance Sheet'!G38 -> 2.2273369 | H5: =SUM('Balance Sheet'!H4:H11)/'Balance Sheet'!H38 -> 2.497532 | I5: =SUM('Balance Sheet'!I4:I11)/'Balance Sheet'!I38 -> 2.7250858 | J5: =SUM('Balance Sheet'!J4:J11)/'Balance Sheet'!J38 -> 2.9496983 | ... L5: =SUM('Balance Sheet'!L4:L11)/'Balance Sheet'!L38 -> 3.330061
B6: Cash Ratio | C6: ='Balance Sheet'!C4/'Balance Sheet'!C38 -> 0.29486907 | D6: ='Balance Sheet'!D4/'Balance Sheet'!D38 -> 0.16352909 | E6: ='Balance Sheet'!E4/'Balance Sheet'!E38 -> 0.19555787 | F6: ='Balance Sheet'!F4/'Balance Sheet'!F38 -> 0.15739326 | G6: ='Balance Sheet'!G4/'Balance Sheet'!G38 -> 0.10534524 | H6: ='Balance Sheet'!H4/'Balance Sheet'!H38 -> 0.35437058 | I6: ='Balance Sheet'!I4/'Balance Sheet'!I38 -> 0.5496636 | J6: ='Balance Sheet'!J4/'Balance Sheet'!J38 -> 0.74766046 | ... L6: ='Balance Sheet'!L4/'Balance Sheet'!L38 -> 1.09198
B7: Solvency Ratios
B8: Debt to Equity | C8: =0/'Balance Sheet'!C52 -> 0 | D8: =0/'Balance Sheet'!D52 -> 0 | E8: =0/'Balance Sheet'!E52 -> 0 | F8: =0/'Balance Sheet'!F52 -> 0 | G8: =0/'Balance Sheet'!G52 -> 0 | H8: =0/'Balance Sheet'!H52 -> 0 | I8: =0/'Balance Sheet'!I52 -> 0 | J8: =0/'Balance Sheet'!J52 -> 0 | ... L8: =0/'Balance Sheet'!L52 -> 0
B9: Debt to Assets | C9: =0/'Balance Sheet'!C28 -> 0 | D9: =0/'Balance Sheet'!D28 -> 0 | E9: =0/'Balance Sheet'!E28 -> 0 | F9: =0/'Balance Sheet'!F28 -> 0 | G9: =0/'Balance Sheet'!G28 -> 0 | H9: =0/'Balance Sheet'!H28 -> 0 | I9: =0/'Balance Sheet'!I28 -> 0 | J9: =0/'Balance Sheet'!J28 -> 0 | ... L9: =0/'Balance Sheet'!L28 -> 0
B10: Interest Coverage Ratio | C10: ='Income Statement'!C11/-'Income Statement'!C13 -> 61.802296 | D10: ='Income Statement'!D11/-'Income Statement'!D13 -> 69.623877 | E10: ='Income Statement'!E11/-'Income Statement'!E13 -> 76.235219 | F10: ='Income Statement'!F11/-'Income Statement'!F13 -> 78.096734 | G10: ='Income Statement'!G11/-'Income Statement'!G13 -> 54.472698 | H10: ='Income Statement'!H11/-'Income Statement'!H13 -> 55.757022 | I10: ='Income Statement'!I11/-'Income Statement'!I13 -> 55.207956 | J10: ='Income Statement'!J11/-'Income Statement'!J13 -> 52.875517 | ... L10: ='Income Statement'!L11/-'Income Statement'!L13 -> 41.446558
B11: Efficiency Ratios
B12: Inventory Turnover | C12: =-SUM('Income Statement'!C4:C5)/'Balance Sheet'!C12 -> 5435.85 | D12: =-SUM('Income Statement'!D4:D5)/'Balance Sheet'!D12 -> 4621.5357 | E12: =-SUM('Income Statement'!E4:E5)/'Balance Sheet'!E12 -> 5136.8929 | F12: =-SUM('Income Statement'!F4:F5)/'Balance Sheet'!F12 -> 7496.9524 | G12: =-SUM('Income Statement'!G4:G5)/'Balance Sheet'!G12 -> 5496.3103 | H12: =-SUM('Income Statement'!H4:H5)/'Balance Sheet'!H12 -> 5626.0207 | I12: =-SUM('Income Statement'!I4:I5)/'Balance Sheet'!I12 -> 5957.5993 | J12: =-SUM('Income Statement'!J4:J5)/'Balance Sheet'!J12 -> 6308.9529 | ... L12: =-SUM('Income Statement'!L4:L5)/'Balance Sheet'!L12 -> 7075.7929
B13: Payable Turnover | C13: =-SUM('Income Statement'!C4:C5)/'Balance Sheet'!C31 -> 13.513611 | D13: =-SUM('Income Statement'!D4:D5)/'Balance Sheet'!D31 -> 12.306515 | E13: =-SUM('Income Statement'!E4:E5)/'Balance Sheet'!E31 -> 14.41068 | F13: =-SUM('Income Statement'!F4:F5)/'Balance Sheet'!F31 -> 11.319002 | G13: =-SUM('Income Statement'!G4:G5)/'Balance Sheet'!G31 -> 10.763979 | H13: =-SUM('Income Statement'!H4:H5)/'Balance Sheet'!H31 -> 12.586207 | I13: =-SUM('Income Statement'!I4:I5)/'Balance Sheet'!I31 -> 12.586207 | J13: =-SUM('Income Statement'!J4:J5)/'Balance Sheet'!J31 -> 12.586207 | ... L13: =-SUM('Income Statement'!L4:L5)/'Balance Sheet'!L31 -> 12.586207
B14: Asset Turnover | C14: ='Income Statement'!C3/'Balance Sheet'!C28 -> 1.3550179 | D14: ='Income Statement'!D3/'Balance Sheet'!D28 -> 1.5694844 | E14: ='Income Statement'!E3/'Balance Sheet'!E28 -> 1.6448934 | F14: ='Income Statement'!F3/'Balance Sheet'!F28 -> 1.5994838 | G14: ='Income Statement'!G3/'Balance Sheet'!G28 -> 1.4641557 | H14: ='Income Statement'!H3/'Balance Sheet'!H28 -> 1.455449 | I14: ='Income Statement'!I3/'Balance Sheet'!I28 -> 1.4295543 | J14: ='Income Statement'!J3/'Balance Sheet'!J28 -> 1.405813 | ... L14: ='Income Statement'!L3/'Balance Sheet'!L28 -> 1.3719822
B15: Profitability Ratios
B16: Gross Profit Margin | C16: ='Income Statement'!C7/'Income Statement'!C3 -> 0.43303921 | D16: ='Income Statement'!D7/'Income Statement'!D3 -> 0.42604388 | E16: ='Income Statement'!E7/'Income Statement'!E3 -> 0.40291748 | F16: ='Income Statement'!F7/'Income Statement'!F3 -> 0.38338738 | G16: ='Income Statement'!G7/'Income Statement'!G3 -> 0.40306942 | H16: ='Income Statement'!H7/'Income Statement'!H3 -> 0.40453461 | I16: ='Income Statement'!I7/'Income Statement'!I3 -> 0.40238949 | J16: ='Income Statement'!J7/'Income Statement'!J3 -> 0.39700806 | ... L16: ='Income Statement'!L7/'Income Statement'!L3 -> 0.3773359
B17: Operating Profit Margin | C17: ='Income Statement'!C11/'Income Statement'!C3 -> 0.25268313 | D17: ='Income Statement'!D11/'Income Statement'!D3 -> 0.24056365 | E17: ='Income Statement'!E11/'Income Statement'!E3 -> 0.24621305 | F17: ='Income Statement'!F11/'Income Statement'!F3 -> 0.24347496 | G17: ='Income Statement'!G11/'Income Statement'!G3 -> 0.2503099 | H17: ='Income Statement'!H11/'Income Statement'!H3 -> 0.2413671 | I17: ='Income Statement'!I11/'Income Statement'!I3 -> 0.22650194 | J17: ='Income Statement'!J11/'Income Statement'!J3 -> 0.20669604 | ... L17: ='Income Statement'!L11/'Income Statement'!L3 -> 0.14917309
B18: Net Profit Margin | C18: ='Income Statement'!C23/'Income Statement'!C3 -> 0.20051211 | D18: ='Income Statement'!D23/'Income Statement'!D3 -> 0.1876314 | E18: ='Income Statement'!E23/'Income Statement'!E3 -> 0.19136712 | F18: ='Income Statement'!F23/'Income Statement'!F3 -> 0.19111795 | G18: ='Income Statement'!G23/'Income Statement'!G3 -> 0.18520641 | H18: ='Income Statement'!H23/'Income Statement'!H3 -> 0.19198542 | I18: ='Income Statement'!I23/'Income Statement'!I3 -> 0.18025218 | J18: ='Income Statement'!J23/'Income Statement'!J3 -> 0.16486098 | ... L18: ='Income Statement'!L23/'Income Statement'!L3 -> 0.12072589
B19: Return on Assets | C19: ='Income Statement'!C23/'Balance Sheet'!C28 -> 0.2716975 | D19: ='Income Statement'!D23/'Balance Sheet'!D28 -> 0.29448455 | E19: ='Income Statement'!E23/'Balance Sheet'!E28 -> 0.31477852 | F19: ='Income Statement'!F23/'Balance Sheet'!F28 -> 0.30569007 | G19: ='Income Statement'!G23/'Balance Sheet'!G28 -> 0.27117101 | H19: ='Income Statement'!H23/'Balance Sheet'!H28 -> 0.279425 | I19: ='Income Statement'!I23/'Balance Sheet'!I28 -> 0.25768028 | J19: ='Income Statement'!J23/'Balance Sheet'!J28 -> 0.23176371 | ... L19: ='Income Statement'!L23/'Balance Sheet'!L28 -> 0.16563378
B20: Return on Equity | C20: ='Income Statement'!C23/'Balance Sheet'!C52 -> 0.42794337 | D20: ='Income Statement'!D23/'Balance Sheet'!D52 -> 0.46381817 | E20: ='Income Statement'!E23/'Balance Sheet'!E52 -> 0.5048128 | F20: ='Income Statement'!F23/'Balance Sheet'!F52 -> 0.50951749 | G20: ='Income Statement'!G23/'Balance Sheet'!G52 -> 0.45588967 | H20: ='Income Statement'!H23/'Balance Sheet'!H52 -> 0.44512759 | I20: ='Income Statement'!I23/'Balance Sheet'!I52 -> 0.3966187 | J20: ='Income Statement'!J23/'Balance Sheet'!J52 -> 0.3469437 | ... L20: ='Income Statement'!L23/'Balance Sheet'!L52 -> 0.23854953
B21: Return on Capital Invested | C21: ='Income Statement'!C11/('Balance Sheet'!C28-'Balance Sheet'!C38) -> 0.48861975 | D21: ='Income Statement'!D11/('Balance Sheet'!D28-'Balance Sheet'!D38) -> 0.54186606 | E21: ='Income Statement'!E11/('Balance Sheet'!E28-'Balance Sheet'!E38) -> 0.59107081 | F21: ='Income Statement'!F11/('Balance Sheet'!F28-'Balance Sheet'!F38) -> 0.58300822 | G21: ='Income Statement'!G11/('Balance Sheet'!G28-'Balance Sheet'!G38) -> 0.55029722 | H21: ='Income Statement'!H11/('Balance Sheet'!H28-'Balance Sheet'!H38) -> 0.5059065 | I21: ='Income Statement'!I11/('Balance Sheet'!I28-'Balance Sheet'!I38) -> 0.45493893 | J21: ='Income Statement'!J11/('Balance Sheet'!J28-'Balance Sheet'!J38) -> 0.40015972 | ... L21: ='Income Statement'!L11/('Balance Sheet'!L28-'Balance Sheet'!L38) -> 0.2741359
B22: ROE DuPont Analysis
B23: Profit Margin | C23: =C18 -> 0.20051211 | D23: =D18 -> 0.1876314 | E23: =E18 -> 0.19136712 | F23: =F18 -> 0.19111795 | G23: =G18 -> 0.18520641 | H23: =H18 -> 0.19198542 | I23: =I18 -> 0.18025218 | J23: =J18 -> 0.16486098 | ... L23: =L18 -> 0.12072589
B24: Asset Turnover | C24: =C14 -> 1.3550179 | D24: =D14 -> 1.5694844 | E24: =E14 -> 1.6448934 | F24: =F14 -> 1.5994838 | G24: =G14 -> 1.4641557 | H24: =H14 -> 1.455449 | I24: =I14 -> 1.4295543 | J24: =J14 -> 1.405813 | ... L24: =L14 -> 1.3719822
B25: Financial Leverage | C25: ='Balance Sheet'!C28/'Balance Sheet'!C52 -> 1.5750729 | D25: ='Balance Sheet'!D28/'Balance Sheet'!D52 -> 1.575017 | E25: ='Balance Sheet'!E28/'Balance Sheet'!E52 -> 1.6037079 | F25: ='Balance Sheet'!F28/'Balance Sheet'!F52 -> 1.666778 | G25: ='Balance Sheet'!G28/'Balance Sheet'!G52 -> 1.6811888 | H25: ='Balance Sheet'!H28/'Balance Sheet'!H52 -> 1.5930128 | I25: ='Balance Sheet'!I28/'Balance Sheet'!I52 -> 1.5391892 | J25: ='Balance Sheet'!J28/'Balance Sheet'!J52 -> 1.4969717 | ... L25: ='Balance Sheet'!L28/'Balance Sheet'!L52 -> 1.4402227
B26: ROE | C26: =C23*C24*C25 -> 0.42794337 | D26: =D23*D24*D25 -> 0.46381817 | E26: =E23*E24*E25 -> 0.5048128 | F26: =F23*F24*F25 -> 0.50951749 | G26: =G23*G24*G25 -> 0.45588967 | H26: =H23*H24*H25 -> 0.44512759 | I26: =I23*I24*I25 -> 0.3966187 | J26: =J23*J24*J25 -> 0.3469437 | ... L26: =L23*L24*L25 -> 0.23854953

Sheet Revenue Built Up
B1: TATA Consultancy Services Ltd | C1: Historicals | H1: Forecasts
B2: (All data in ₹ Crore, except per share Information) | C2: FY 2022 | D2: FY2023 | E2: FY 2024 | F2: FY 2025 | G2: FY 2026 | H2: FY 2027 | I2: FY 2028 | J2: FY 2029 | K2: FY 2030 | L2: FY 2031
B3: Segments
B4: BFSI | C4: 75126 | D4: 86127 | E4: 90928 | F4: 94597 | G4: 103363 | H4: =G4*(1+H13) -> 111115.22 | I4: =H4*(1+I13) -> 117782.14 | J4: =I4*(1+J13) -> 123671.25 | K4: =J4*(1+K13) -> 127381.38 | L4: =K4*(1+L13) -> 131202.82
B5: Manufacturing | C5: 18610 | D5: 21236 | E5: 23491 | F5: 25170 | G5: 26614 | H5: =G5*(1+H14) -> 28743.12 | I5: =H5*(1+I14) -> 31042.57 | J5: =I5*(1+J14) -> 32905.124 | K5: =J5*(1+K14) -> 34879.431 | L5: =K5*(1+L14) -> 36972.197
B6: Consumer Business | C6: 30715 | D6: 37506 | E6: 39357 | F6: 40197 | G6: 42432 | H6: =G6*(1+H15) -> 43704.96 | I6: =H6*(1+I15) -> 45016.109 | J6: =I6*(1+J15) -> 46366.592 | K6: =J6*(1+K15) -> 47757.59 | L6: =K6*(1+L15) -> 49190.318
B7: Communication, Media & Technology | C7: 31874 | D7: 37653 | E7: 39391 | F7: 45893 | G7: 39474 | H7: =G7*(1+H16) -> 41447.7 | I7: =H7*(1+I16) -> 43520.085 | J7: =I7*(1+J16) -> 45696.089 | K7: =J7*(1+K16) -> 47980.894 | L7: =K7*(1+L16) -> 50379.938
B8: Life Sciences & Healthcare | C8: 20462 | D8: 24605 | E8: 26745 | F8: 26456 | G8: 27745 | H8: =G8*(1+H17) -> 28299.9 | I8: =H8*(1+I17) -> 28865.898 | J8: =I8*(1+J17) -> 29443.216 | K8: =J8*(1+K17) -> 30032.08 | L8: =K8*(1+L17) -> 30632.722
B9: Others | C9: 14967 | D9: 18331 | E9: 20981 | F9: 23011 | G9: 27393 | H9: =G9*(1+H18) -> 30132.3 | I9: =H9*(1+I18) -> 32844.207 | J9: =I9*(1+J18) -> 35800.186 | K9: =J9*(1+K18) -> 39022.202 | L9: =K9*(1+L18) -> 42534.201
B10: Total Revenue | C10: =SUM(C4:C9) -> 191754 | D10: =SUM(D4:D9) -> 225458 | E10: =SUM(E4:E9) -> 240893 | F10: =SUM(F4:F9) -> 255324 | G10: =SUM(G4:G9) -> 267021 | H10: =SUM(H4:H9) -> 283443.21 | I10: =SUM(I4:I9) -> 299071.01 | J10: =SUM(J4:J9) -> 313882.45 | ... L10: =SUM(L4:L9) -> 340912.2
B11: % YoY
B12: Segments
B13: BFSI | D13: =D4/C4-1 -> 0.14643399 | E13: =E4/D4-1 -> 0.055743263 | F13: =F4/E4-1 -> 0.040350607 | G13: =G4/F4-1 -> 0.092666786 | H13: 0.075 | I13: 0.06 | J13: 0.05 | K13: 0.03 | L13: 0.03
B14: Manufacturing | D14: =D5/C5-1 -> 0.14110693 | E14: =E5/D5-1 -> 0.10618761 | F14: =F5/E5-1 -> 0.071474182 | G14: =G5/F5-1 -> 0.057369885 | H14: 0.08 | I14: 0.08 | J14: 0.06 | K14: 0.06 | L14: 0.06
B15: Consumer Business | D15: =D6/C6-1 -> 0.22109718 | E15: =E6/D6-1 -> 0.049352104 | F15: =F6/E6-1 -> 0.02134309 | G15: =G6/F6-1 -> 0.055601164 | H15: 0.03 | I15: 0.03 | J15: 0.03 | K15: 0.03 | L15: 0.03
B16: Communication, Media & Technology | D16: =D7/C7-1 -> 0.18130765 | E16: =E7/D7-1 -> 0.046158341 | F16: =F7/E7-1 -> 0.16506309 | G16: =G7/F7-1 -> -0.13986883 | H16: 0.05 | I16: 0.05 | J16: 0.05 | K16: 0.05 | L16: 0.05
B17: Life Sciences & Healthcare | D17: =D8/C8-1 -> 0.20247288 | E17: =E8/D8-1 -> 0.086974192 | F17: =F8/E8-1 -> -0.010805758 | G17: =G8/F8-1 -> 0.048722407 | H17: 0.02 | I17: 0.02 | J17: 0.02 | K17: 0.02 | L17: 0.02
B18: Others | D18: =D9/C9-1 -> 0.22476114 | E18: =E9/D9-1 -> 0.14456385 | F18: =F9/E9-1 -> 0.096754206 | G18: =G9/F9-1 -> 0.19043066 | H18: 0.1 | I18: 0.09 | J18: 0.09 | K18: 0.09 | L18: 0.09

Sheet Cost Sheet
B1: TATA Consultancy Services Ltd | C1: Historicals | H1: Forecasts
B2: (All data in ₹ Crore, except per share Information) | C2: FY 2022 | D2: FY2023 | E2: FY 2024 | F2: FY 2025 | G2: FY 2026 | H2: FY 2027 | I2: FY 2028 | J2: FY 2029 | K2: FY 2030 | L2: FY 2031
B3: Revenue | C3: ='Income Statement'!C3 -> 191754 | D3: ='Income Statement'!D3 -> 225458 | E3: ='Income Statement'!E3 -> 240893 | F3: ='Income Statement'!F3 -> 255324 | G3: ='Income Statement'!G3 -> 267021 | H3: ='Income Statement'!H3 -> 283443.21 | I3: ='Income Statement'!I3 -> 299071.01 | J3: ='Income Statement'!J3 -> 313882.45 | ... L3: ='Income Statement'!L3 -> 340912.2
B5: Employee Expenses | C5: =-'Income Statement'!C4 -> 107554 | D5: =-'Income Statement'!D4 -> 127522 | E5: =-'Income Statement'!E4 -> 140131 | F5: =-'Income Statement'!F4 -> 145788 | G5: =-'Income Statement'!G4 -> 154994 | H5: =G5*(1+H6) -> 164293.64 | I5: =H5*(1+I6) -> 174151.26 | J5: =I5*(1+J6) -> 184600.33 | K5: =J5*(1+K6) -> 195676.35 | L5: =K5*(1+L6) -> 207416.94
B6: Total Emplyees (Crore) | C6: 0.05 | D6: 0.061 | E6: 0.06 | F6: 0.06 | G6: 0.06 | H6: =G6 -> 0.06 | I6: =H6 -> 0.06 | J6: =I6 -> 0.06 | K6: =J6 -> 0.06 | L6: =K6 -> 0.06
B7: Cost per Employee (Lakh) | C7: =C5/C6 -> 2151080 | D7: =D5/D6 -> 2090524.6 | E7: =E5/E6 -> 2335516.7 | F7: =F5/F6 -> 2429800 | G7: =G5/G6 -> 2583233.3 | H7: =H5/H6 -> 2738227.3 | I7: =I5/I6 -> 2902521 | J7: =J5/J6 -> 3076672.2 | ... L7: =L5/L6 -> 3456948.9
B9: Cost of equipment & software licences | C9: =-'Income Statement'!C5 -> 1163 | D9: =-'Income Statement'!D5 -> 1881 | E9: =-'Income Statement'!E5 -> 3702 | F9: =-'Income Statement'!F5 -> 11648 | G9: =-'Income Statement'!G5 -> 4399 | H9: =G9*(1+H10) -> 4486.98 | I9: =H9*(1+I10) -> 4576.7196 | J9: =I9*(1+J10) -> 4668.254 | K9: =J9*(1+K10) -> 4761.6191 | L9: =K9*(1+L10) -> 4856.8515
B10: % of Revenue | C10: =C9/C3 -> 0.0060650625 | D10: =D9/D3 -> 0.0083430173 | E10: =E9/E3 -> 0.015367819 | F10: =F9/F3 -> 0.045620467 | G10: =G9/G3 -> 0.01647436 | H10: 0.02 | I10: 0.02 | J10: 0.02 | K10: 0.02 | L10: 0.02
B11: Cost of Services sold | C11: =C5+C9 -> 108717 | D11: =D5+D9 -> 129403 | E11: =E5+E9 -> 143833 | F11: =F5+F9 -> 157436 | G11: =G5+G9 -> 159393 | H11: =H5+H9 -> 168780.62 | I11: =I5+I9 -> 178727.98 | J11: =J5+J9 -> 189268.59 | ... L11: =L5+L9 -> 212273.79
B13: Other Expenses | C13: =-'Income Statement'!C8 -> 29980 | D13: =-'Income Statement'!D8 -> 36796 | E13: =-'Income Statement'!E8 -> 32764 | F13: =-'Income Statement'!F8 -> 30481 | G13: =-'Income Statement'!G8 -> 35230 | H13: =G13*(1+H14) -> 39986.05 | I13: =H13*(1+I14) -> 45384.167 | J13: =I13*(1+J14) -> 51511.029 | K13: =J13*(1+K14) -> 58465.018 | L13: =K13*(1+L14) -> 66357.796
B14: % of Revenue | C14: =C13/C3 -> 0.15634615 | D14: =D13/D3 -> 0.16320556 | E14: =E13/E3 -> 0.13601059 | F14: =F13/F3 -> 0.11938165 | G14: =G13/G3 -> 0.13193719 | H14: 0.135 | I14: 0.135 | J14: 0.135 | K14: 0.135 | L14: 0.135

Sheet Working Cap
B1: TATA Consultancy Services Ltd | C1: Historicals | H1: Forecasts
B2: (All data in ₹ Crore, except per share Information) | C2: FY 2022 | D2: FY2023 | E2: FY 2024 | F2: FY 2025 | G2: FY 2026 | H2: FY 2027 | I2: FY 2028 | J2: FY 2029 | K2: FY 2030 | L2: FY 2031
B3: Revenue | C3: ='Income Statement'!C3 -> 191754 | D3: ='Income Statement'!D3 -> 225458 | E3: ='Income Statement'!E3 -> 240893 | F3: ='Income Statement'!F3 -> 255324 | G3: ='Income Statement'!G3 -> 267021 | H3: ='Income Statement'!H3 -> 283443.21 | I3: ='Income Statement'!I3 -> 299071.01 | J3: ='Income Statement'!J3 -> 313882.45 | ... L3: ='Income Statement'!L3 -> 340912.2
B4: Cost of services sold | C4: =-'Income Statement'!C6 -> 108717 | D4: =-'Income Statement'!D6 -> 129403 | E4: =-'Income Statement'!E6 -> 143833 | F4: =-'Income Statement'!F6 -> 157436 | G4: =-'Income Statement'!G6 -> 159393 | H4: =-'Income Statement'!H6 -> 168780.62 | I4: =-'Income Statement'!I6 -> 178727.98 | J4: =-'Income Statement'!J6 -> 189268.59 | ... L4: =-'Income Statement'!L6 -> 212273.79
B6: Receivables | C6: ='Balance Sheet'!C6 -> 41810 | D6: ='Balance Sheet'!D6 -> 49954 | E6: ='Balance Sheet'!E6 -> 53577 | F6: ='Balance Sheet'!F6 -> 59046 | G6: ='Balance Sheet'!G6 -> 67714 | H6: =(H3*H13)/365 -> 66007.322 | I6: =(I3*I13)/365 -> 69646.673 | J6: =(J3*J13)/365 -> 73095.914 | K6: =(K3*K13)/365 -> 76163.162 | L6: =(L3*L13)/365 -> 79390.512
B7: Payables | C7: ='Balance Sheet'!C31 -> 8045 | D7: ='Balance Sheet'!D31 -> 10515 | E7: ='Balance Sheet'!E31 -> 9981 | F7: ='Balance Sheet'!F31 -> 13909 | G7: ='Balance Sheet'!G31 -> 14808 | H7: =(H4*H14)/365 -> 13409.967 | I7: =(I4*I14)/365 -> 14200.305 | J7: =(J4*J14)/365 -> 15037.778 | K7: =(K4*K14)/365 -> 15925.209 | L7: =(L4*L14)/365 -> 16865.589
B9: Net Working Capital | C9: =C6-C7 -> 33765 | D9: =D6-D7 -> 39439 | E9: =E6-E7 -> 43596 | F9: =F6-F7 -> 45137 | G9: =G6-G7 -> 52906 | H9: =H6-H7 -> 52597.355 | I9: =I6-I7 -> 55446.368 | J9: =J6-J7 -> 58058.135 | ... L9: =L6-L7 -> 62524.924
B10: (Increase)/Decrease in Working Capital | D10: =C9-D9 -> -5674 | E10: =D9-E9 -> -4157 | F10: =E9-F9 -> -1541 | G10: =F9-G9 -> -7769 | H10: =G9-H9 -> 308.64536 | I10: =H9-I9 -> -2849.0131 | J10: =I9-J9 -> -2611.7675 | K10: =J9-K9 -> -2179.8184 | L10: =K9-L9 -> -2286.97
B12: Ratios & Assumptions
B13: Days sales outstaning | C13: =(C6/C3)*365 -> 79.58452 | D13: =(D6/D3)*365 -> 80.87187 | E13: =(E6/E3)*365 -> 81.179632 | F13: =(F6/F3)*365 -> 84.409574 | G13: =(G6/G3)*365 -> 92.560548 | H13: 85 | I13: 85 | J13: 85 | K13: 85 | L13: 85
B14: Days Payable outstanding | C14: =(C7/C4)*365 -> 27.009805 | D14: =(D7/D4)*365 -> 29.659088 | E14: =(E7/E4)*365 -> 25.328436 | F14: =(F7/F4)*365 -> 32.246659 | G14: =(G7/G4)*365 -> 33.909394 | H14: 29 | I14: 29 | J14: 29 | K14: 29 | L14: 29

Sheet Dep & Capex
B1: TATA Consultancy Services Ltd | C1: Historicals | H1: Forecasts
B2: (All data in ₹ Crore, except per share Information) | C2: FY 2022 | D2: FY2023 | E2: FY 2024 | F2: FY 2025 | G2: FY 2026 | H2: FY 2027 | I2: FY 2028 | J2: FY 2029 | K2: FY 2030 | L2: FY 2031
B3: Revenue | C3: ='Income Statement'!C3 -> 191754 | D3: ='Income Statement'!D3 -> 225458 | E3: ='Income Statement'!E3 -> 240893 | F3: ='Income Statement'!F3 -> 255324 | G3: ='Income Statement'!G3 -> 267021 | H3: ='Income Statement'!H3 -> 283443.21 | I3: ='Income Statement'!I3 -> 299071.01 | J3: ='Income Statement'!J3 -> 313882.45 | ... L3: ='Income Statement'!L3 -> 340912.2
B4: Capex | C4: =-SUM('Cash Flows '!C38:C40) -> 2995 | D4: =-SUM('Cash Flows '!D38:D40) -> 3100 | E4: =-SUM('Cash Flows '!E38:E40) -> 2674 | F4: =-SUM('Cash Flows '!F38:F40) -> 3937 | G4: =-SUM('Cash Flows '!G38:G40) -> 4146 | H4: =H3*H5 -> 5668.8641 | I4: =I3*I5 -> 5981.4201 | J4: =J3*J5 -> 6277.649 | K4: =K3*K5 -> 8176.3395 | L4: =L3*L5 -> 8522.805
B5: % of Revenue | C5: =C4/C3 -> 0.01561897 | D5: =D4/D3 -> 0.013749789 | E5: =E4/E3 -> 0.011100364 | F5: =F4/F3 -> 0.015419624 | G5: =G4/G3 -> 0.015526869 | H5: 0.02 | I5: 0.02 | J5: 0.02 | K5: 0.025 | L5: 0.025
B7: Beginning Net PP&E | H7: =G11 -> 11032 | I7: =H11 -> 10438.195 | J7: =I11 -> 9200.9153 | K7: =J11 -> 7253.9884 | L7: =K11 -> 6020.1595
B8: Capital Expenditures | H8: =H4 -> 5668.8641 | I8: =I4 -> 5981.4201 | J8: =J4 -> 6277.649 | K8: =K4 -> 8176.3395 | L8: =L4 -> 8522.805
B9: (Depreciation Expense) | H9: =-H104 -> -6262.6694 | I9: =-I104 -> -7218.6996 | J9: =-J104 -> -8224.576 | K9: =-K104 -> -9410.1683 | L9: =-L104 -> -11425.691
B10: (Asset Sales ) | H10: 0 | I10: 0 | J10: 0 | K10: 0 | L10: 0
B11: Ending Net PP&E | G11: ='Balance Sheet'!G15 -> 11032 | H11: =SUM(H7:H10) -> 10438.195 | I11: =SUM(I7:I10) -> 9200.9153 | J11: =SUM(J7:J10) -> 7253.9884 | K11: =SUM(K7:K10) -> 6020.1595 | L11: =SUM(L7:L10) -> 3117.2739
B12: PPE (Break-up for FY25) | C12: Amount | D12: Useful Life Years | E12: Proportion of Assets
A13: 1 | B13: Buildings | C13: 8752 | D13: 20 | E13: =C13/$C$21 -> 0.24777759
A14: 2 | B14: Lease hold improvements | C14: 2790 | D14: 15 | E14: =C14/$C$21 -> 0.0789876
A15: 3 | B15: Plant & Equipment | C15: 993 | D15: 10 | E15: =C15/$C$21 -> 0.028112791
A16: 4 | B16: Computers | C16: 14948 | D16: 4 | E16: =C16/$C$21 -> 0.42319234
A17: 5 | B17: Vechile | C17: 53 | D17: 4 | E17: =C17/$C$21 -> 0.0015004813
A18: 6 | B18: Office Equipment | C18: 3160 | D18: 5 | E18: =C18/$C$21 -> 0.089462658
A19: 7 | B19: Electrical Installations | C19: 2329 | D19: 10 | E19: =C19/$C$21 -> 0.065936244
A20: 8 | B20: Furniture & Fixtures | C20: 2297 | D20: 5 | E20: =C20/$C$21 -> 0.065030293
B21: Grosss PPE | C21: =SUM(C13:C20) -> 35322 | E21: =SUM(E13:E20) -> 1
B22: Total Capex Breakup | C22: =C2 -> FY 2022 | D22: =D2 -> FY2023 | E22: =E2 -> FY 2024 | F22: =F2 -> FY 2025 | G22: =G2 -> FY 2026 | H22: =H2 -> FY 2027 | I22: =I2 -> FY 2028 | J22: =J2 -> FY 2029 | ... L22: =L2 -> FY 2031
B23: Buildings | C23: =C$4*$E13 -> 742.09388 | D23: =D$4*$E13 -> 768.11053 | E23: =E$4*$E13 -> 662.55727 | F23: =F$4*$E13 -> 975.50037 | G23: =G$4*$E13 -> 1027.2859 | H23: =H$4*$E13 -> 1404.6175 | I23: =I$4*$E13 -> 1482.0619 | J23: =J$4*$E13 -> 1555.4607 | ... L23: =L$4*$E13 -> 2111.7601
B24: Lease hold improvements | C24: =C$4*$E14 -> 236.56786 | D24: =D$4*$E14 -> 244.86156 | E24: =E$4*$E14 -> 211.21284 | F24: =F$4*$E14 -> 310.97418 | G24: =G$4*$E14 -> 327.48259 | H24: =H$4*$E14 -> 447.76997 | I24: =I$4*$E14 -> 472.45802 | J24: =J$4*$E14 -> 495.85643 | ... L24: =L$4*$E14 -> 673.19591
B25: Plant & Equipment | C25: =C$4*$E15 -> 84.197809 | D25: =D$4*$E15 -> 87.149652 | E25: =E$4*$E15 -> 75.173603 | F25: =F$4*$E15 -> 110.68006 | G25: =G$4*$E15 -> 116.55563 | H25: =H$4*$E15 -> 159.36759 | I25: =I$4*$E15 -> 168.15441 | J25: =J$4*$E15 -> 176.48223 | ... L25: =L$4*$E15 -> 239.59983
B26: Computers | C26: =C$4*$E16 -> 1267.4611 | D26: =D$4*$E16 -> 1311.8963 | E26: =E$4*$E16 -> 1131.6163 | F26: =F$4*$E16 -> 1666.1083 | G26: =G$4*$E16 -> 1754.5555 | H26: =H$4*$E16 -> 2399.0199 | I26: =I$4*$E16 -> 2531.2912 | J26: =J$4*$E16 -> 2656.653 | ... L26: =L$4*$E16 -> 3606.7858
B27: Vechile | C27: =C$4*$E17 -> 4.4939415 | D27: =D$4*$E17 -> 4.651492 | E27: =E$4*$E17 -> 4.012287 | F27: =F$4*$E17 -> 5.9073948 | G27: =G$4*$E17 -> 6.2209954 | H27: =H$4*$E17 -> 8.5060245 | I27: =I$4*$E17 -> 8.975009 | J27: =J$4*$E17 -> 9.4194949 | ... L27: =L$4*$E17 -> 12.788309
B28: Office Equipment | C28: =C$4*$E18 -> 267.94066 | D28: =D$4*$E18 -> 277.33424 | E28: =E$4*$E18 -> 239.22315 | F28: =F$4*$E18 -> 352.21448 | G28: =G$4*$E18 -> 370.91218 | H28: =H$4*$E18 -> 507.15165 | I28: =I$4*$E18 -> 535.11374 | J28: =J$4*$E18 -> 561.61517 | ... L28: =L$4*$E18 -> 762.47279
B29: Electrical Installations | C29: =C$4*$E19 -> 197.47905 | D29: =D$4*$E19 -> 204.40236 | E29: =E$4*$E19 -> 176.31352 | F29: =F$4*$E19 -> 259.59099 | G29: =G$4*$E19 -> 273.37167 | H29: =H$4*$E19 -> 373.7836 | I29: =I$4*$E19 -> 394.39238 | J29: =J$4*$E19 -> 413.9246 | ... L29: =L$4*$E19 -> 561.96175
B30: Furniture & Fixtures | C30: =C$4*$E20 -> 194.76573 | D30: =D$4*$E20 -> 201.59391 | E30: =E$4*$E20 -> 173.891 | F30: =F$4*$E20 -> 256.02426 | G30: =G$4*$E20 -> 269.61559 | H30: =H$4*$E20 -> 368.64789 | I30: =I$4*$E20 -> 388.9735 | J30: =J$4*$E20 -> 408.23735 | ... L30: =L$4*$E20 -> 554.2405
A31: Strightline Method
A32: 1 | B32: Buildings | C32: =C13 -> 8752
B33: Useful Life | C33: =D13 -> 20 | H33: =$C$32/$C$33 -> 437.6 | I33: =$C$32/$C$33 -> 437.6 | J33: =$C$32/$C$33 -> 437.6 | K33: =$C$32/$C$33 -> 437.6 | L33: =$C$32/$C$33 -> 437.6
C34: Year | D34: Capex | E34: Useful life
C35: FY 2027 | D35: {=TRANSPOSE(H23:L23)} -> 1404.6175 | E35: =$C$33 -> 20 | H35: =$D$35/$E$35/2 -> 35.115437 | I35: =$D$35/$E$35 -> 70.230874 | J35: =$D$35/$E$35 -> 70.230874 | K35: =$D$35/$E$35 -> 70.230874 | L35: =$D$35/$E$35 -> 70.230874
C36: FY 2028 | D36: 1482.0619 | E36: =$C$33 -> 20 | I36: =$D$36/$E$36/2 -> 37.051547 | J36: =$D$36/$E$36 -> 74.103093 | K36: =$D$36/$E$36 -> 74.103093 | L36: =$D$36/$E$36 -> 74.103093
C37: FY 2029 | D37: 1555.4607 | E37: =$C$33 -> 20 | J37: =$D$37/$E$37/2 -> 38.886519 | K37: =$D$37/$E$37 -> 77.773037 | L37: =$D$37/$E$37 -> 77.773037
C38: FY 2030 | D38: 2025.9137 | E38: =$C$33 -> 20 | K38: =$D$38/$E$38/2 -> 50.647842 | L38: =$D$38/$E$38 -> 101.29568
C39: FY 2031 | D39: 2111.7601 | E39: =$C$33 -> 20 | L39: =$D$39/$E$39/2 -> 52.794002
B40: Buildings Depreciation | H40: =SUM(H33:H39) -> 472.71544 | I40: =SUM(I33:I39) -> 544.88242 | J40: =SUM(J33:J39) -> 620.82049 | K40: =SUM(K33:K39) -> 710.35485 | L40: =SUM(L33:L39) -> 813.79669
A41: 2 | B41: Lease hold improvements | C41: =C14 -> 2790
...

Sheet DCF 
A1: DCF Valuation | G1: (All data in ₹ Crore, includeing per share Information) | L1: WACC Caluation
A2: Assumptions | L2: Company | M2: Market Cap | N2: Debt | O2: Debt/Equity | P2: Debt/Capital | Q2: Tax Rate | R2: Levered Beta | S2: Unlevered Beta
B3: Transaction Date | C3: 46285 | I3: Terminal Value | L3: ='Relative Valuation'!B14 -> Infosys | M3: ='Relative Valuation'!F14 -> 436677.96 | N3: ='Relative Valuation'!G14 -> 8737 | O3: =N3/M3 -> 0.020007879 | P3: =N3/SUM(M3:N3) -> 0.019615417 | Q3: 0.27 | R3: 0.71 | S3: =R3/(1+O3)*(1-Q3) -> 0.50813333
B4: Financial Year end | C4: 46477 | I4: EV/EBITDA | J4: =(I16+I19)*C6 -> 809478.29 | L4: ='Relative Valuation'!B15 -> HCL Technologies | M4: ='Relative Valuation'!F15 -> 339022.54 | N4: ='Relative Valuation'!G15 -> 5215 | O4: =N4/M4 -> 0.015382458 | P4: =N4/SUM(M4:N4) -> 0.015149423 | Q4: 0.27 | R4: 0.77 | S4: =R4/(1+O4)*(1-Q4) -> 0.55358451
B5: Tax Rate | C5: ='Income Statement'!H32 -> 0.24482722 | I5: Perpectual | J5: =I22*(1+C8)/(C7-C8) -> 895561.47 | L5: ='Relative Valuation'!B16 -> Wipro | M5: ='Relative Valuation'!F16 -> 174706.04 | N5: ='Relative Valuation'!G16 -> 20291 | O5: =N5/M5 -> 0.11614366 | P5: =N5/SUM(M5:N5) -> 0.10405799 | Q5: 0.27 | R5: 0.68 | S5: =R5/(1+O5)*(1-Q5) -> 0.44474562
B6: EV/EBITDA | C6: ='Relative Valuation'!N21 -> 12.997275 | I6: Average | J6: =AVERAGE(J4:J5) -> 852519.88 | L6: ='Relative Valuation'!B17 -> Tech Mahindra | M6: ='Relative Valuation'!F17 -> 150482.09 | N6: ='Relative Valuation'!G17 -> 2186.2 | O6: =N6/M6 -> 0.014527975 | P6: =N6/SUM(M6:N6) -> 0.014319935 | Q6: 0.27 | R6: 0.58 | S6: =R6/(1+O6)*(1-Q6) -> 0.41733694
B7: Discount Rate | C7: =M34 -> 0.074392018 | L7: ='Relative Valuation'!B18 -> LTM | M7: ='Relative Valuation'!F18 -> 126671.21 | N7: ='Relative Valuation'!G18 -> 2310 | O7: =N7/M7 -> 0.018236188 | P7: =N7/SUM(M7:N7) -> 0.017909585 | Q7: 0.27 | R7: 1.04 | S7: =R7/(1+O7)*(1-Q7) -> 0.74560304
B8: Growth Rate | C8: 0.03 | L8: ='Relative Valuation'!B19 -> Persistent Systems | M8: ='Relative Valuation'!F19 -> 83731.36 | N8: ='Relative Valuation'!G19 -> 477.45 | O8: =N8/M8 -> 0.0057021646 | P8: =N8/SUM(M8:N8) -> 0.0056698343 | Q8: 0.27 | R8: 0.91 | S8: =R8/(1+O8)*(1-Q8) -> 0.66053353
B9: Shares Outstanding in Crore | C9: ='Relative Valuation'!E23 -> 361.81 | L9: Average | O9: =AVERAGE(O3:O8) -> 0.031666721 | P9: =AVERAGE(P3:P8) -> 0.029453697 | Q9: =AVERAGE(Q3:Q8) -> 0.27 | R9: =AVERAGE(R3:R8) -> 0.78166667 | S9: =AVERAGE(S3:S8) -> 0.55498949
L10: Median | O10: =MEDIAN(O3:O8) -> 0.016809323 | P10: =MEDIAN(P3:P8) -> 0.016529504 | Q10: =MEDIAN(Q3:Q8) -> 0.27 | R10: =MEDIAN(R3:R8) -> 0.74 | S10: =MEDIAN(S3:S8) -> 0.53085892
B11: Discounted Cash Flows | D11: Entry | E11: 2027 | F11: =E11+1 -> 2028 | G11: =F11+1 -> 2029 | H11: =G11+1 -> 2030 | I11: =H11+1 -> 2031 | J11: Exit
B12: Date | D12: =C3 -> 46285 | E12: =C4 -> 46477 | F12: 46843 | G12: 47208 | H12: 47573 | I12: 47938 | J12: 47938 | L12: TCS | M12: ='Relative Valuation'!F23 -> 761610.05 | N12: ='Relative Valuation'!G23 -> 11283
B13: Time Period | E13: 0 | F13: 1 | G13: 2 | H13: 3 | I13: 4
B14: Yearfrac | E14: =YEARFRAC(D12,E12) -> 0.53055556 | F14: =YEARFRAC(E12,F12) -> 1 | G14: =YEARFRAC(F12,G12) -> 1 | H14: =YEARFRAC(G12,H12) -> 1 | I14: =YEARFRAC(H12,I12) -> 1 | J14: =I14 -> 1
L15: WACC
B16: EBIT | E16: ='Income Statement'!H11 -> 68413.866 | F16: ='Income Statement'!I11 -> 67740.163 | G16: ='Income Statement'!J11 -> 64878.259 | H16: ='Income Statement'!K11 -> 58740.421 | I16: ='Income Statement'!L11 -> 50854.927 | L16: Industry Mix
B17: Less: Taxes | E17: =SUM('Income Statement'!H21:H22) -> -17171.903 | F17: =SUM('Income Statement'!I21:I22) -> -17006.962 | G17: =SUM('Income Statement'!J21:J22) -> -16306.29 | H17: =SUM('Income Statement'!K21:K22) -> -14803.58 | I17: =SUM('Income Statement'!L21:L22) -> -12872.997 | L17: Proportion of Debt | M17: =P9 -> 0.029453697
B18: NOPAT | E18: =SUM(E16:E17) -> 51241.963 | F18: =SUM(F16:F17) -> 50733.201 | G18: =SUM(G16:G17) -> 48571.969 | H18: =SUM(H16:H17) -> 43936.84 | I18: =SUM(I16:I17) -> 37981.93 | L18: Proportion of Equity | M18: =1-M17 -> 0.9705463
B19: Add: Depreciation & Amortization | E19: =-'Income Statement'!H10 -> 6262.6694 | F19: =-'Income Statement'!I10 -> 7218.6996 | G19: =-'Income Statement'!J10 -> 8224.576 | H19: =-'Income Statement'!K10 -> 9410.1683 | I19: =-'Income Statement'!L10 -> 11425.691 | L19: Company Mix
B20: Less: Capex | E20: ='Cash Flows '!H38 -> -5668.8641 | F20: ='Cash Flows '!I38 -> -5981.4201 | G20: ='Cash Flows '!J38 -> -6277.649 | H20: ='Cash Flows '!K38 -> -8176.3395 | I20: ='Cash Flows '!L38 -> -8522.805 | L20: Market Cap | M20: =M12 -> 761610.05
B21: Less: Changes in Working Capital | E21: =SUM('Cash Flows '!H24,'Cash Flows '!H27) -> 308.64536 | F21: =SUM('Cash Flows '!I24,'Cash Flows '!I27) -> -2849.0131 | G21: =SUM('Cash Flows '!J24,'Cash Flows '!J27) -> -2611.7675 | H21: =SUM('Cash Flows '!K24,'Cash Flows '!K27) -> -2179.8184 | I21: =SUM('Cash Flows '!L24,'Cash Flows '!L27) -> -2286.97 | L21: Total Debt | M21: =N12 -> 11283
B22: Free Cash Flow to Firm | E22: =SUM(E18:E21) -> 52144.413 | F22: =SUM(F18:F21) -> 49121.467 | G22: =SUM(G18:G21) -> 47907.128 | H22: =SUM(H18:H21) -> 42990.851 | I22: =SUM(I18:I21) -> 38597.846 | J22: =J6 -> 852519.88 | L22: Debt / Equity | M22: =M21/M20 -> 0.014814668
L23: Cost of Debt
B24: Transaction FCFF | E24: =E22*E14 -> 27665.508 | F24: =F22*F14 -> 49121.467 | G24: =G22*G14 -> 47907.128 | H24: =H22*H14 -> 42990.851 | I24: =I22*I14 -> 38597.846 | J24: =J22*J14 -> 852519.88 | L24: Pre-Tax Cost of Debt | M24: ='Balance Sheet'!G59 -> 0.075259976
L25: Tax Rate | M25: ='Income Statement'!H32 -> 0.24482722
B26: Intrinsic Value | L26: After-Tax Cost of Debt | M26: =M24*(1-M25) -> 0.056834285
B27: Enterprise Value | E27: =XNPV(C7,E24:J24,E12:J12) -> 818178.69 | L27: Cost of Equity
B28: Add: Cash & Cash Eq | E28: =SUM('Balance Sheet'!H4:H5) -> 27581.708 | L28: Risk Free Rate | M28: 0.069
B29: Less: Debt | E29: =-SUM('Balance Sheet'!H30,'Balance Sheet'!H41) -> -11283 | L29: Equity Market Return | M29: ='Equity Return'!F5 -> 0.083998188
B30: Less: Non-Controlling Interest | E30: 0 | L30: Equity Risk Premium | M30: =M29-M28 -> 0.014998188
B31: Equity Value | E31: =SUM(E27:E30) -> 834477.39 | L31: Levered Equity Beta | M31: =S10/(1+M22)*(1-M25) -> 0.39503785
L32: Cost of Equity | M32: =M28+M31*M30 -> 0.074924852
B33: Implied Share price per Share | E33: =E31/C9 -> 2306.3967
B34: Current Market Price | E34: 2130 | L34: WACC | M34: =(M17*M26)+(M18*M32) -> 0.074392018
B35: Upside Potential % | E35: =E33/E34-1 -> 0.082815359
A37: Sensitivity Analysis
F38: Exit Multiples
E39: =E33 -> 2306.3967 | F39: =G39-2.5 -> 7.9972747 | G39: =H39-2.5 -> 10.497275 | H39: 12.997275 | I39: =H39+2.5 -> 15.497275 | J39: =I39+2.5 -> 17.997275
D40: Discount Rate | E40: 0.0544 | F40: 2935.2245 | G40: 3109.284 | H40: 3283.3435 | I40: 3457.403 | J40: 3631.4625
E41: 0.0644 | F41: 2327.7117 | G41: 2495.3173 | H41: 2662.923 | I41: 2830.5286 | J41: 2998.1343
...

Sheet Relative Valuation
A1: Relative Valauation | K1: (All data in ₹ Crore, including per share Information)
A2: Peer Data
B3: Company | C3: CMP Rs. | D3: Shares | E3: Mar Cap | F3: Debt | G3: Cash | H3: Sales | I3: EBIDTA | J3: PAT
B4: TCS | C4: 2105 | D4: 361.81 | E4: 761607.42 | F4: 11283 | G4: 12908 | H4: 275859 | I4: 76450 | J4: 53690.47
B5: Infosys | C5: 1051.4 | D5: 415.33 | E5: 426682.56 | F5: 8737 | G5: 22201 | H5: 184582 | I5: 46226 | J5: 31174.41
B6: HCL Technologies | C6: 1249.3 | D6: 271.37 | E6: 339018.18 | F6: 5215 | G6: 23425 | H6: 134374 | I6: 28122 | J6: 18130.33
B7: Wipro | C7: 166.83 | D7: 1047.21 | E7: 165244.04 | F7: 20291 | G7: 10555.5 | H7: 94968 | I7: 21671.3 | J7: 13219
B8: Tech Mahindra | C8: 1537.1 | D8: 97.9 | E8: 150656.36 | F8: 2186.2 | G8: 5105.4 | H8: 59176.1 | I8: 9056.9 | J8: 5320.57
B9: LTM | C9: 4275.1 | D9: 29.63 | E9: 126808.58 | F9: 2310 | G9: 2812.4 | H9: 44075 | I9: 8649.6 | J9: 5609.89
B10: Persistent Systems | C10: 5416 | D10: 15.46 | E10: 85437.4 | F10: 477.45 | G10: 1218.25 | H10: 15718.1 | I10: 2970.2 | J10: 1990.12
D12: Market Data | J12: Financial Data | M12: Valuation
B13: Company | C13: Ticker | D13: CMP | E13: Shares in crore | F13: Market Cap | G13: Debt | H13: Cash | I13: EV | J13: Sales | K13: EBITDA | L13: Net Income | M13: EV/Sales | N13: EV/EBITDA | O13: P/E
B14: =B5 -> Infosys | C14: INFY | D14: =C5 -> 1051.4 | E14: =D5 -> 415.33 | F14: =D14*E14 -> 436677.96 | G14: =F5 -> 8737 | H14: =G5 -> 22201 | I14: =SUM(F14,G14)-H14 -> 423213.96 | J14: =H5 -> 184582 | K14: =I5 -> 46226 | L14: =J5 -> 31174.41 | M14: =I14/J14 -> 2.2928236 | N14: =I14/K14 -> 9.155323 | O14: =F14/L14 -> 14.007577
B15: =B6 -> HCL Technologies | C15: HCLTECH | D15: =C6 -> 1249.3 | E15: =D6 -> 271.37 | F15: =D15*E15 -> 339022.54 | G15: =F6 -> 5215 | H15: =G6 -> 23425 | I15: =SUM(F15,G15)-H15 -> 320812.54 | J15: =H6 -> 134374 | K15: =I6 -> 28122 | L15: =J6 -> 18130.33 | M15: =I15/J15 -> 2.3874599 | N15: =I15/K15 -> 11.407885 | O15: =F15/L15 -> 18.699193
B16: =B7 -> Wipro | C16: WIPRO | D16: =C7 -> 166.83 | E16: =D7 -> 1047.21 | F16: =D16*E16 -> 174706.04 | G16: =F7 -> 20291 | H16: =G7 -> 10555.5 | I16: =SUM(F16,G16)-H16 -> 184441.54 | J16: =H7 -> 94968 | K16: =I7 -> 21671.3 | L16: =J7 -> 13219 | M16: =I16/J16 -> 1.9421441 | N16: =I16/K16 -> 8.5108666 | O16: =F16/L16 -> 13.216283
B17: =B8 -> Tech Mahindra | C17: TECHM | D17: =C8 -> 1537.1 | E17: =D8 -> 97.9 | F17: =D17*E17 -> 150482.09 | G17: =F8 -> 2186.2 | H17: =G8 -> 5105.4 | I17: =SUM(F17,G17)-H17 -> 147562.89 | J17: =H8 -> 59176.1 | K17: =I8 -> 9056.9 | L17: =J8 -> 5320.57 | M17: =I17/J17 -> 2.4936231 | N17: =I17/K17 -> 16.29287 | O17: =F17/L17 -> 28.283077
B18: =B9 -> LTM | C18: LTM | D18: =C9 -> 4275.1 | E18: =D9 -> 29.63 | F18: =D18*E18 -> 126671.21 | G18: =F9 -> 2310 | H18: =G9 -> 2812.4 | I18: =SUM(F18,G18)-H18 -> 126168.81 | J18: =H9 -> 44075 | K18: =I9 -> 8649.6 | L18: =J9 -> 5609.89 | M18: =I18/J18 -> 2.8625936 | N18: =I18/K18 -> 14.586664 | O18: =F18/L18 -> 22.579982
B19: =B10 -> Persistent Systems | C19: PERSISTENT | D19: =C10 -> 5416 | E19: =D10 -> 15.46 | F19: =D19*E19 -> 83731.36 | G19: =F10 -> 477.45 | H19: =G10 -> 1218.25 | I19: =SUM(F19,G19)-H19 -> 82990.56 | J19: =H10 -> 15718.1 | K19: =I10 -> 2970.2 | L19: =J10 -> 1990.12 | M19: =I19/J19 -> 5.2799359 | N19: =I19/K19 -> 27.941068 | O19: =F19/L19 -> 42.073523
B20: Average | M20: =AVERAGE(M14:M19) -> 2.87643 | N20: =AVERAGE(N14:N19) -> 14.649113 | O20: =AVERAGE(O14:O19) -> 23.143273
